Workbook

Sheet Инструкция
B2: P&L магазина товаров для дома на маркетплейсах — модель на 2027 год
B4: Зачем
B5: Собственник спрашивает: сколько мы заработаем за год, какие товары и каналы убыточны и что будет, если поднять цену или урезать рекламу.
B7: Как устроено
B8: 1. «Допущения» — комиссии, логистика, выкуп, ДРР по каналам, налог, постоянные расходы, сезонность и сценарии.
B9: 2. «Товары» — ассортимент: цена, себестоимость, план заказов в месяц и распределение по каналам.
B10: 3. «Юнит-экономика» — прибыль с одной проданной единицы по каждому товару в каждом канале и предельный ДРР.
B11: 4. «P&L» — помесячный отчёт о прибылях и убытках с учётом сезонности и роста, итоги по каналам и категориям, график.
B12: 5. «Чувствительность» — годовая операционная прибыль при разной цене и доле рекламы (таблица «что, если»).
B14: Обозначения
B15: Синий шрифт — вводимые значения, их можно менять. Чёрный — формулы, не трогать. Зелёный — ссылка на другой лист.
B16: Жёлтая заливка — ключевые допущения и переключатель сценария (лист «Допущения», ячейка C22).
... B24: Данные демонстрационные. Спрос не зависит от цены (эластичность не моделируется). Логистика — средняя за единицу, без учёта габаритов и складов.

Sheet Допущения
B2: Допущения
B3: Синие ячейки можно менять. Источник цифр по умолчанию — типичные тарифы и показатели продавца товаров для дома (демонстрационные).
B5: Канал | C5: Комиссия, % от цены | D5: Логистика до покупателя, ₽/шт | E5: Обратная логистика, ₽/шт | F5: Выкуп, % | G5: ДРР, % от цены | H5: Хранение, ₽/шт
B6: Wildberries | C6: 0.24 | D6: 92 | E6: 50 | F6: 0.78 | G6: 0.12 | H6: 18
B7: Ozon | C7: 0.21 | D7: 85 | E7: 45 | F7: 0.85 | G7: 0.1 | H7: 15
B8: Сайт | C8: 0.035 | D8: 160 | E8: 160 | F8: 0.95 | G8: 0.13 | H8: 0
B11: Налог (УСН «доходы»), % от выручки | C11: 0.06
B12: Постоянные расходы, ₽ в месяц | C12: 450000
B13: Рост продаж, % в месяц | C13: 0.02
B16: Сценарий | C16: Изменение цены | D16: Множитель ДРР | E16: Изменение выкупа, п.п. | F16: Изменение спроса
B17: Базовый | C17: 0 | D17: 1 | E17: 0 | F17: 0
B18: Оптимистичный | C18: 0.05 | D18: 0.85 | E18: 0.03 | F18: 0.1
B19: Пессимистичный | C19: -0.05 | D19: 1.3 | E19: -0.05 | F19: -0.15
B22: Выбранный сценарий ▸ | C22: Базовый
B23: Изменение цены | C23: =INDEX($C$17:$C$19,MATCH($C$22,$B$17:$B$19,0)) -> 0
B24: Множитель ДРР | C24: =INDEX($D$17:$D$19,MATCH($C$22,$B$17:$B$19,0)) -> 1
B25: Изменение выкупа, п.п. | C25: =INDEX($E$17:$E$19,MATCH($C$22,$B$17:$B$19,0)) -> 0
B26: Изменение спроса | C26: =INDEX($F$17:$F$19,MATCH($C$22,$B$17:$B$19,0)) -> 0
B29: Сезонность (индекс месяца, 1,00 = средний месяц)
C30: янв | D30: фев | E30: мар | F30: апр | G30: май | H30: июн | I30: июл | J30: авг | K30: сен | L30: окт | M30: ноя | N30: дек
B31: Индекс | C31: 0.92 | D31: 0.88 | E31: 1.08 | F31: 0.93 | G31: 0.94 | H31: 0.86 | I31: 0.87 | J31: 0.97 | K31: 1.02 | L31: 1 | M31: 1.13 | N31: 1.4
B32: Проверка: среднее индексов | C32: =AVERAGE(C31:N31) -> 1

Sheet Товары
B2: Ассортимент и план заказов
B3: Заказы — до выкупа. Доля сайта считается как остаток. Цены и себестоимость демонстрационные.
B5: SKU | C5: Товар | D5: Категория | E5: Цена, ₽ | F5: Себестоимость, ₽ | G5: Заказов в месяц, шт | H5: Доля WB | I5: Доля Ozon | J5: Доля сайта
B6: DU-0001 | C6: Плед вязаный | D6: Текстиль | E6: 2490 | F6: 980 | G6: 420 | H6: 0.55 | I6: 0.3 | J6: =1-H6-I6 -> 0.15
B7: DU-0002 | C7: Комплект постельного белья | D7: Текстиль | E7: 3990 | F7: 1650 | G7: 300 | H7: 0.5 | I7: 0.3 | J7: =1-H7-I7 -> 0.2
B8: DU-0003 | C8: Полотенце махровое | D8: Текстиль | E8: 890 | F8: 340 | G8: 650 | H8: 0.5 | I8: 0.35 | J8: =1-H8-I8 -> 0.15
B9: DU-0004 | C9: Кружка керамическая | D9: Посуда | E9: 690 | F9: 230 | G9: 900 | H9: 0.45 | I9: 0.35 | J9: =1-H9-I9 -> 0.2
B10: DU-0005 | C10: Набор тарелок | D10: Посуда | E10: 2890 | F10: 1150 | G10: 260 | H10: 0.4 | I10: 0.35 | J10: =1-H10-I10 -> 0.25
B11: DU-0006 | C11: Френч-пресс | D11: Посуда | E11: 1490 | F11: 560 | G11: 380 | H11: 0.45 | I11: 0.35 | J11: =1-H11-I11 -> 0.2
B12: DU-0007 | C12: Органайзер для ящика | D12: Хранение | E12: 590 | F12: 260 | G12: 520 | H12: 0.55 | I12: 0.3 | J12: =1-H12-I12 -> 0.15
B13: DU-0008 | C13: Корзина плетёная | D13: Хранение | E13: 690 | F13: 380 | G13: 480 | H13: 0.55 | I13: 0.35 | J13: =1-H13-I13 -> 0.1
B14: DU-0009 | C14: Свеча ароматическая | D14: Декор | E14: 490 | F14: 210 | G14: 1100 | H14: 0.5 | I14: 0.35 | J14: =1-H14-I14 -> 0.15
B15: DU-0010 | C15: Ваза стеклянная | D15: Декор | E15: 1890 | F15: 720 | G15: 240 | H15: 0.4 | I15: 0.35 | J15: =1-H15-I15 -> 0.25
B16: DU-0011 | C16: Коврик для ванной | D16: Ванная | E16: 1290 | F16: 520 | G16: 360 | H16: 0.5 | I16: 0.35 | J16: =1-H16-I16 -> 0.15
B17: DU-0012 | C17: Держатель для щёток | D17: Ванная | E17: 390 | F17: 190 | G17: 700 | H17: 0.55 | I17: 0.35 | J17: =1-H17-I17 -> 0.1
C18: Итого / средневзвешенно | E18: =SUMPRODUCT(E6:E17,G6:G17)/G18 -> 1129.6197 | F18: =SUMPRODUCT(F6:F17,G6:G17)/G18 -> 457.68621 | G18: =SUM(G6:G17) -> 6310

Sheet Юнит-экономика
A1: Юнит-экономика по товарам и каналам (месяц со средней сезонностью)
A2: Логистика на 1 выкуп = (логистика до покупателя + обратная × доля невыкупа) / выкуп. Предельный ДРР — доля рекламы, при которой прибыль с единицы = 0. Серые столбцы справа — вспомогательные.
A4: SKU | B4: Канал | C4: Товар | D4: Категория | E4: Цена, ₽ | F4: Себест., ₽ | G4: Комиссия, ₽ | H4: Логистика на 1 выкуп, ₽ | I4: Хранение, ₽ | J4: Реклама, ₽ | K4: Налог, ₽ | L4: Прибыль с 1 шт, ₽ | M4: Маржин-сть, % | N4: Предельный ДРР, % | O4: Заказов в мес | P4: Выкуп, % | Q4: Продаж в мес | R4: Выручка в мес, ₽ | S4: Прибыль в мес, ₽ | T4: Базовая цена, ₽ | U4: Комиссия, % | V4: Логистика, ₽/шт | W4: Обратная, ₽/шт
A5: DU-0001 | B5: Wildberries | C5: =INDEX(Товары!$C$6:$C$17,MATCH($A5,Товары!$B$6:$B$17,0)) -> Плед вязаный | D5: =INDEX(Товары!$D$6:$D$17,MATCH($A5,Товары!$B$6:$B$17,0)) -> Текстиль | E5: =T5*(1+Допущения!$C$23) -> 2490 | F5: =INDEX(Товары!$F$6:$F$17,MATCH($A5,Товары!$B$6:$B$17,0)) -> 980 | G5: =E5*U5 -> 597.6 | H5: =(V5+W5*(1-P5))/P5 -> 132.05128 | I5: =INDEX(Допущения!$H$6:$H$8,MATCH($B5,Допущения!$B$6:$B$8,0)) -> 18 | J5: =E5*INDEX(Допущения!$G$6:$G$8,MATCH($B5,Допущения!$B$6:$B$8,0))*Допущения!$C$24 -> 298.8 | K5: =E5*Допущения!$C$11 -> 149.4 | L5: =E5-F5-G5-H5-I5-J5-K5 -> 314.14872 | M5: =IFERROR(L5/E5,0) -> 0.12616414 | N5: =IFERROR((E5-F5-G5-H5-I5-K5)/E5,0) -> 0.24616414 | O5: =INDEX(Товары!$G$6:$G$17,MATCH($A5,Товары!$B$6:$B$17,0))*INDEX(Товары!$H$6:$H$17,MATCH($A5,Товары!$B$6:$B$17,0))*(1+Допущения!$C$26) -> 231 | P5: =MAX(0.05,MIN(1,INDEX(Допущения!$F$6:$F$8,MATCH($B5,Допущения!$B$6:$B$8,0))+Допущения!$C$25)) -> 0.78 | Q5: =O5*P5 -> 180.18 | R5: =Q5*E5 -> 448648.2 | S5: =Q5*L5 -> 56603.316 | T5: =INDEX(Товары!$E$6:$E$17,MATCH($A5,Товары!$B$6:$B$17,0)) -> 2490 | U5: =INDEX(Допущения!$C$6:$C$8,MATCH($B5,Допущения!$B$6:$B$8,0)) -> 0.24 | V5: =INDEX(Допущения!$D$6:$D$8,MATCH($B5,Допущения!$B$6:$B$8,0)) -> 92 | W5: =INDEX(Допущения!$E$6:$E$8,MATCH($B5,Допущения!$B$6:$B$8,0)) -> 50
A6: DU-0001 | B6: Ozon | C6: =INDEX(Товары!$C$6:$C$17,MATCH($A6,Товары!$B$6:$B$17,0)) -> Плед вязаный | D6: =INDEX(Товары!$D$6:$D$17,MATCH($A6,Товары!$B$6:$B$17,0)) -> Текстиль | E6: =T6*(1+Допущения!$C$23) -> 2490 | F6: =INDEX(Товары!$F$6:$F$17,MATCH($A6,Товары!$B$6:$B$17,0)) -> 980 | G6: =E6*U6 -> 522.9 | H6: =(V6+W6*(1-P6))/P6 -> 107.94118 | I6: =INDEX(Допущения!$H$6:$H$8,MATCH($B6,Допущения!$B$6:$B$8,0)) -> 15 | J6: =E6*INDEX(Допущения!$G$6:$G$8,MATCH($B6,Допущения!$B$6:$B$8,0))*Допущения!$C$24 -> 249 | K6: =E6*Допущения!$C$11 -> 149.4 | L6: =E6-F6-G6-H6-I6-J6-K6 -> 465.75882 | M6: =IFERROR(L6/E6,0) -> 0.18705174 | N6: =IFERROR((E6-F6-G6-H6-I6-K6)/E6,0) -> 0.28705174 | O6: =INDEX(Товары!$G$6:$G$17,MATCH($A6,Товары!$B$6:$B$17,0))*INDEX(Товары!$I$6:$I$17,MATCH($A6,Товары!$B$6:$B$17,0))*(1+Допущения!$C$26) -> 126 | P6: =MAX(0.05,MIN(1,INDEX(Допущения!$F$6:$F$8,MATCH($B6,Допущения!$B$6:$B$8,0))+Допущения!$C$25)) -> 0.85 | Q6: =O6*P6 -> 107.1 | R6: =Q6*E6 -> 266679 | S6: =Q6*L6 -> 49882.77 | T6: =INDEX(Товары!$E$6:$E$17,MATCH($A6,Товары!$B$6:$B$17,0)) -> 2490 | U6: =INDEX(Допущения!$C$6:$C$8,MATCH($B6,Допущения!$B$6:$B$8,0)) -> 0.21 | V6: =INDEX(Допущения!$D$6:$D$8,MATCH($B6,Допущения!$B$6:$B$8,0)) -> 85 | W6: =INDEX(Допущения!$E$6:$E$8,MATCH($B6,Допущения!$B$6:$B$8,0)) -> 45
A7: DU-0001 | B7: Сайт | C7: =INDEX(Товары!$C$6:$C$17,MATCH($A7,Товары!$B$6:$B$17,0)) -> Плед вязаный | D7: =INDEX(Товары!$D$6:$D$17,MATCH($A7,Товары!$B$6:$B$17,0)) -> Текстиль | E7: =T7*(1+Допущения!$C$23) -> 2490 | F7: =INDEX(Товары!$F$6:$F$17,MATCH($A7,Товары!$B$6:$B$17,0)) -> 980 | G7: =E7*U7 -> 87.15 | H7: =(V7+W7*(1-P7))/P7 -> 176.84211 | I7: =INDEX(Допущения!$H$6:$H$8,MATCH($B7,Допущения!$B$6:$B$8,0)) -> 0 | J7: =E7*INDEX(Допущения!$G$6:$G$8,MATCH($B7,Допущения!$B$6:$B$8,0))*Допущения!$C$24 -> 323.7 | K7: =E7*Допущения!$C$11 -> 149.4 | L7: =E7-F7-G7-H7-I7-J7-K7 -> 772.90789 | M7: =IFERROR(L7/E7,0) -> 0.31040478 | N7: =IFERROR((E7-F7-G7-H7-I7-K7)/E7,0) -> 0.44040478 | O7: =INDEX(Товары!$G$6:$G$17,MATCH($A7,Товары!$B$6:$B$17,0))*INDEX(Товары!$J$6:$J$17,MATCH($A7,Товары!$B$6:$B$17,0))*(1+Допущения!$C$26) -> 63 | P7: =MAX(0.05,MIN(1,INDEX(Допущения!$F$6:$F$8,MATCH($B7,Допущения!$B$6:$B$8,0))+Допущения!$C$25)) -> 0.95 | Q7: =O7*P7 -> 59.85 | R7: =Q7*E7 -> 149026.5 | S7: =Q7*L7 -> 46258.537 | T7: =INDEX(Товары!$E$6:$E$17,MATCH($A7,Товары!$B$6:$B$17,0)) -> 2490 | U7: =INDEX(Допущения!$C$6:$C$8,MATCH($B7,Допущения!$B$6:$B$8,0)) -> 0.035 | V7: =INDEX(Допущения!$D$6:$D$8,MATCH($B7,Допущения!$B$6:$B$8,0)) -> 160 | W7: =INDEX(Допущения!$E$6:$E$8,MATCH($B7,Допущения!$B$6:$B$8,0)) -> 160
A8: DU-0002 | B8: Wildberries | C8: =INDEX(Товары!$C$6:$C$17,MATCH($A8,Товары!$B$6:$B$17,0)) -> Комплект постельного белья | D8: =INDEX(Товары!$D$6:$D$17,MATCH($A8,Товары!$B$6:$B$17,0)) -> Текстиль | E8: =T8*(1+Допущения!$C$23) -> 3990 | F8: =INDEX(Товары!$F$6:$F$17,MATCH($A8,Товары!$B$6:$B$17,0)) -> 1650 | G8: =E8*U8 -> 957.6 | H8: =(V8+W8*(1-P8))/P8 -> 132.05128 | I8: =INDEX(Допущения!$H$6:$H$8,MATCH($B8,Допущения!$B$6:$B$8,0)) -> 18 | J8: =E8*INDEX(Допущения!$G$6:$G$8,MATCH($B8,Допущения!$B$6:$B$8,0))*Допущения!$C$24 -> 478.8 | K8: =E8*Допущения!$C$11 -> 239.4 | L8: =E8-F8-G8-H8-I8-J8-K8 -> 514.14872 | M8: =IFERROR(L8/E8,0) -> 0.12885933 | N8: =IFERROR((E8-F8-G8-H8-I8-K8)/E8,0) -> 0.24885933 | O8: =INDEX(Товары!$G$6:$G$17,MATCH($A8,Товары!$B$6:$B$17,0))*INDEX(Товары!$H$6:$H$17,MATCH($A8,Товары!$B$6:$B$17,0))*(1+Допущения!$C$26) -> 150 | P8: =MAX(0.05,MIN(1,INDEX(Допущения!$F$6:$F$8,MATCH($B8,Допущения!$B$6:$B$8,0))+Допущения!$C$25)) -> 0.78 | Q8: =O8*P8 -> 117 | R8: =Q8*E8 -> 466830 | S8: =Q8*L8 -> 60155.4 | T8: =INDEX(Товары!$E$6:$E$17,MATCH($A8,Товары!$B$6:$B$17,0)) -> 3990 | U8: =INDEX(Допущения!$C$6:$C$8,MATCH($B8,Допущения!$B$6:$B$8,0)) -> 0.24 | V8: =INDEX(Допущения!$D$6:$D$8,MATCH($B8,Допущения!$B$6:$B$8,0)) -> 92 | W8: =INDEX(Допущения!$E$6:$E$8,MATCH($B8,Допущения!$B$6:$B$8,0)) -> 50
A9: DU-0002 | B9: Ozon | C9: =INDEX(Товары!$C$6:$C$17,MATCH($A9,Товары!$B$6:$B$17,0)) -> Комплект постельного белья | D9: =INDEX(Товары!$D$6:$D$17,MATCH($A9,Товары!$B$6:$B$17,0)) -> Текстиль | E9: =T9*(1+Допущения!$C$23) -> 3990 | F9: =INDEX(Товары!$F$6:$F$17,MATCH($A9,Товары!$B$6:$B$17,0)) -> 1650 | G9: =E9*U9 -> 837.9 | H9: =(V9+W9*(1-P9))/P9 -> 107.94118 | I9: =INDEX(Допущения!$H$6:$H$8,MATCH($B9,Допущения!$B$6:$B$8,0)) -> 15 | J9: =E9*INDEX(Допущения!$G$6:$G$8,MATCH($B9,Допущения!$B$6:$B$8,0))*Допущения!$C$24 -> 399 | K9: =E9*Допущения!$C$11 -> 239.4 | L9: =E9-F9-G9-H9-I9-J9-K9 -> 740.75882 | M9: =IFERROR(L9/E9,0) -> 0.18565384 | N9: =IFERROR((E9-F9-G9-H9-I9-K9)/E9,0) -> 0.28565384 | O9: =INDEX(Товары!$G$6:$G$17,MATCH($A9,Товары!$B$6:$B$17,0))*INDEX(Товары!$I$6:$I$17,MATCH($A9,Товары!$B$6:$B$17,0))*(1+Допущения!$C$26) -> 90 | P9: =MAX(0.05,MIN(1,INDEX(Допущения!$F$6:$F$8,MATCH($B9,Допущения!$B$6:$B$8,0))+Допущения!$C$25)) -> 0.85 | Q9: =O9*P9 -> 76.5 | R9: =Q9*E9 -> 305235 | S9: =Q9*L9 -> 56668.05 | T9: =INDEX(Товары!$E$6:$E$17,MATCH($A9,Товары!$B$6:$B$17,0)) -> 3990 | U9: =INDEX(Допущения!$C$6:$C$8,MATCH($B9,Допущения!$B$6:$B$8,0)) -> 0.21 | V9: =INDEX(Допущения!$D$6:$D$8,MATCH($B9,Допущения!$B$6:$B$8,0)) -> 85 | W9: =INDEX(Допущения!$E$6:$E$8,MATCH($B9,Допущения!$B$6:$B$8,0)) -> 45
A10: DU-0002 | B10: Сайт | C10: =INDEX(Товары!$C$6:$C$17,MATCH($A10,Товары!$B$6:$B$17,0)) -> Комплект постельного белья | D10: =INDEX(Товары!$D$6:$D$17,MATCH($A10,Товары!$B$6:$B$17,0)) -> Текстиль | E10: =T10*(1+Допущения!$C$23) -> 3990 | F10: =INDEX(Товары!$F$6:$F$17,MATCH($A10,Товары!$B$6:$B$17,0)) -> 1650 | G10: =E10*U10 -> 139.65 | H10: =(V10+W10*(1-P10))/P10 -> 176.84211 | I10: =INDEX(Допущения!$H$6:$H$8,MATCH($B10,Допущения!$B$6:$B$8,0)) -> 0 | J10: =E10*INDEX(Допущения!$G$6:$G$8,MATCH($B10,Допущения!$B$6:$B$8,0))*Допущения!$C$24 -> 518.7 | K10: =E10*Допущения!$C$11 -> 239.4 | L10: =E10-F10-G10-H10-I10-J10-K10 -> 1265.4079 | M10: =IFERROR(L10/E10,0) -> 0.31714484 | N10: =IFERROR((E10-F10-G10-H10-I10-K10)/E10,0) -> 0.44714484 | O10: =INDEX(Товары!$G$6:$G$17,MATCH($A10,Товары!$B$6:$B$17,0))*INDEX(Товары!$J$6:$J$17,MATCH($A10,Товары!$B$6:$B$17,0))*(1+Допущения!$C$26) -> 60 | P10: =MAX(0.05,MIN(1,INDEX(Допущения!$F$6:$F$8,MATCH($B10,Допущения!$B$6:$B$8,0))+Допущения!$C$25)) -> 0.95 | Q10: =O10*P10 -> 57 | R10: =Q10*E10 -> 227430 | S10: =Q10*L10 -> 72128.25 | T10: =INDEX(Товары!$E$6:$E$17,MATCH($A10,Товары!$B$6:$B$17,0)) -> 3990 | U10: =INDEX(Допущения!$C$6:$C$8,MATCH($B10,Допущения!$B$6:$B$8,0)) -> 0.035 | V10: =INDEX(Допущения!$D$6:$D$8,MATCH($B10,Допущения!$B$6:$B$8,0)) -> 160 | W10: =INDEX(Допущения!$E$6:$E$8,MATCH($B10,Допущения!$B$6:$B$8,0)) -> 160
A11: DU-0003 | B11: Wildberries | C11: =INDEX(Товары!$C$6:$C$17,MATCH($A11,Товары!$B$6:$B$17,0)) -> Полотенце махровое | D11: =INDEX(Товары!$D$6:$D$17,MATCH($A11,Товары!$B$6:$B$17,0)) -> Текстиль | E11: =T11*(1+Допущения!$C$23) -> 890 | F11: =INDEX(Товары!$F$6:$F$17,MATCH($A11,Товары!$B$6:$B$17,0)) -> 340 | G11: =E11*U11 -> 213.6 | H11: =(V11+W11*(1-P11))/P11 -> 132.05128 | I11: =INDEX(Допущения!$H$6:$H$8,MATCH($B11,Допущения!$B$6:$B$8,0)) -> 18 | J11: =E11*INDEX(Допущения!$G$6:$G$8,MATCH($B11,Допущения!$B$6:$B$8,0))*Допущения!$C$24 -> 106.8 | K11: =E11*Допущения!$C$11 -> 53.4 | L11: =E11-F11-G11-H11-I11-J11-K11 -> 26.148718 | M11: =IFERROR(L11/E11,0) -> 0.029380582 | N11: =IFERROR((E11-F11-G11-H11-I11-K11)/E11,0) -> 0.14938058 | O11: =INDEX(Товары!$G$6:$G$17,MATCH($A11,Товары!$B$6:$B$17,0))*INDEX(Товары!$H$6:$H$17,MATCH($A11,Товары!$B$6:$B$17,0))*(1+Допущения!$C$26) -> 325 | P11: =MAX(0.05,MIN(1,INDEX(Допущения!$F$6:$F$8,MATCH($B11,Допущения!$B$6:$B$8,0))+Допущения!$C$25)) -> 0.78 | Q11: =O11*P11 -> 253.5 | R11: =Q11*E11 -> 225615 | S11: =Q11*L11 -> 6628.7 | T11: =INDEX(Товары!$E$6:$E$17,MATCH($A11,Товары!$B$6:$B$17,0)) -> 890 | U11: =INDEX(Допущения!$C$6:$C$8,MATCH($B11,Допущения!$B$6:$B$8,0)) -> 0.24 | V11: =INDEX(Допущения!$D$6:$D$8,MATCH($B11,Допущения!$B$6:$B$8,0)) -> 92 | W11: =INDEX(Допущения!$E$6:$E$8,MATCH($B11,Допущения!$B$6:$B$8,0)) -> 50
A12: DU-0003 | B12: Ozon | C12: =INDEX(Товары!$C$6:$C$17,MATCH($A12,Товары!$B$6:$B$17,0)) -> Полотенце махровое | D12: =INDEX(Товары!$D$6:$D$17,MATCH($A12,Товары!$B$6:$B$17,0)) -> Текстиль | E12: =T12*(1+Допущения!$C$23) -> 890 | F12: =INDEX(Товары!$F$6:$F$17,MATCH($A12,Товары!$B$6:$B$17,0)) -> 340 | G12: =E12*U12 -> 186.9 | H12: =(V12+W12*(1-P12))/P12 -> 107.94118 | I12: =INDEX(Допущения!$H$6:$H$8,MATCH($B12,Допущения!$B$6:$B$8,0)) -> 15 | J12: =E12*INDEX(Допущения!$G$6:$G$8,MATCH($B12,Допущения!$B$6:$B$8,0))*Допущения!$C$24 -> 89 | K12: =E12*Допущения!$C$11 -> 53.4 | L12: =E12-F12-G12-H12-I12-J12-K12 -> 97.758824 | M12: =IFERROR(L12/E12,0) -> 0.10984137 | N12: =IFERROR((E12-F12-G12-H12-I12-K12)/E12,0) -> 0.20984137 | O12: =INDEX(Товары!$G$6:$G$17,MATCH($A12,Товары!$B$6:$B$17,0))*INDEX(Товары!$I$6:$I$17,MATCH($A12,Товары!$B$6:$B$17,0))*(1+Допущения!$C$26) -> 227.5 | P12: =MAX(0.05,MIN(1,INDEX(Допущения!$F$6:$F$8,MATCH($B12,Допущения!$B$6:$B$8,0))+Допущения!$C$25)) -> 0.85 | Q12: =O12*P12 -> 193.375 | R12: =Q12*E12 -> 172103.75 | S12: =Q12*L12 -> 18904.112 | T12: =INDEX(Товары!$E$6:$E$17,MATCH($A12,Товары!$B$6:$B$17,0)) -> 890 | U12: =INDEX(Допущения!$C$6:$C$8,MATCH($B12,Допущения!$B$6:$B$8,0)) -> 0.21 | V12: =INDEX(Допущения!$D$6:$D$8,MATCH($B12,Допущения!$B$6:$B$8,0)) -> 85 | W12: =INDEX(Допущения!$E$6:$E$8,MATCH($B12,Допущения!$B$6:$B$8,0)) -> 45
A13: DU-0003 | B13: Сайт | C13: =INDEX(Товары!$C$6:$C$17,MATCH($A13,Товары!$B$6:$B$17,0)) -> Полотенце махровое | D13: =INDEX(Товары!$D$6:$D$17,MATCH($A13,Товары!$B$6:$B$17,0)) -> Текстиль | E13: =T13*(1+Допущения!$C$23) -> 890 | F13: =INDEX(Товары!$F$6:$F$17,MATCH($A13,Товары!$B$6:$B$17,0)) -> 340 | G13: =E13*U13 -> 31.15 | H13: =(V13+W13*(1-P13))/P13 -> 176.84211 | I13: =INDEX(Допущения!$H$6:$H$8,MATCH($B13,Допущения!$B$6:$B$8,0)) -> 0 | J13: =E13*INDEX(Допущения!$G$6:$G$8,MATCH($B13,Допущения!$B$6:$B$8,0))*Допущения!$C$24 -> 115.7 | K13: =E13*Допущения!$C$11 -> 53.4 | L13: =E13-F13-G13-H13-I13-J13-K13 -> 172.90789 | M13: =IFERROR(L13/E13,0) -> 0.19427853 | N13: =IFERROR((E13-F13-G13-H13-I13-K13)/E13,0) -> 0.32427853 | O13: =INDEX(Товары!$G$6:$G$17,MATCH($A13,Товары!$B$6:$B$17,0))*INDEX(Товары!$J$6:$J$17,MATCH($A13,Товары!$B$6:$B$17,0))*(1+Допущения!$C$26) -> 97.5 | P13: =MAX(0.05,MIN(1,INDEX(Допущения!$F$6:$F$8,MATCH($B13,Допущения!$B$6:$B$8,0))+Допущения!$C$25)) -> 0.95 | Q13: =O13*P13 -> 92.625 | R13: =Q13*E13 -> 82436.25 | S13: =Q13*L13 -> 16015.594 | T13: =INDEX(Товары!$E$6:$E$17,MATCH($A13,Товары!$B$6:$B$17,0)) -> 890 | U13: =INDEX(Допущения!$C$6:$C$8,MATCH($B13,Допущения!$B$6:$B$8,0)) -> 0.035 | V13: =INDEX(Допущения!$D$6:$D$8,MATCH($B13,Допущения!$B$6:$B$8,0)) -> 160 | W13: =INDEX(Допущения!$E$6:$E$8,MATCH($B13,Допущения!$B$6:$B$8,0)) -> 160
A14: DU-0004 | B14: Wildberries | C14: =INDEX(Товары!$C$6:$C$17,MATCH($A14,Товары!$B$6:$B$17,0)) -> Кружка керамическая | D14: =INDEX(Товары!$D$6:$D$17,MATCH($A14,Товары!$B$6:$B$17,0)) -> Посуда | E14: =T14*(1+Допущения!$C$23) -> 690 | F14: =INDEX(Товары!$F$6:$F$17,MATCH($A14,Товары!$B$6:$B$17,0)) -> 230 | G14: =E14*U14 -> 165.6 | H14: =(V14+W14*(1-P14))/P14 -> 132.05128 | I14: =INDEX(Допущения!$H$6:$H$8,MATCH($B14,Допущения!$B$6:$B$8,0)) -> 18 | J14: =E14*INDEX(Допущения!$G$6:$G$8,MATCH($B14,Допущения!$B$6:$B$8,0))*Допущения!$C$24 -> 82.8 | K14: =E14*Допущения!$C$11 -> 41.4 | L14: =E14-F14-G14-H14-I14-J14-K14 -> 20.148718 | M14: =IFERROR(L14/E14,0) -> 0.029201041 | N14: =IFERROR((E14-F14-G14-H14-I14-K14)/E14,0) -> 0.14920104 | O14: =INDEX(Товары!$G$6:$G$17,MATCH($A14,Товары!$B$6:$B$17,0))*INDEX(Товары!$H$6:$H$17,MATCH($A14,Товары!$B$6:$B$17,0))*(1+Допущения!$C$26) -> 405 | P14: =MAX(0.05,MIN(1,INDEX(Допущения!$F$6:$F$8,MATCH($B14,Допущения!$B$6:$B$8,0))+Допущения!$C$25)) -> 0.78 | Q14: =O14*P14 -> 315.9 | R14: =Q14*E14 -> 217971 | S14: =Q14*L14 -> 6364.98 | T14: =INDEX(Товары!$E$6:$E$17,MATCH($A14,Товары!$B$6:$B$17,0)) -> 690 | U14: =INDEX(Допущения!$C$6:$C$8,MATCH($B14,Допущения!$B$6:$B$8,0)) -> 0.24 | V14: =INDEX(Допущения!$D$6:$D$8,MATCH($B14,Допущения!$B$6:$B$8,0)) -> 92 | W14: =INDEX(Допущения!$E$6:$E$8,MATCH($B14,Допущения!$B$6:$B$8,0)) -> 50
A15: DU-0004 | B15: Ozon | C15: =INDEX(Товары!$C$6:$C$17,MATCH($A15,Товары!$B$6:$B$17,0)) -> Кружка керамическая | D15: =INDEX(Товары!$D$6:$D$17,MATCH($A15,Товары!$B$6:$B$17,0)) -> Посуда | E15: =T15*(1+Допущения!$C$23) -> 690 | F15: =INDEX(Товары!$F$6:$F$17,MATCH($A15,Товары!$B$6:$B$17,0)) -> 230 | G15: =E15*U15 -> 144.9 | H15: =(V15+W15*(1-P15))/P15 -> 107.94118 | I15: =INDEX(Допущения!$H$6:$H$8,MATCH($B15,Допущения!$B$6:$B$8,0)) -> 15 | J15: =E15*INDEX(Допущения!$G$6:$G$8,MATCH($B15,Допущения!$B$6:$B$8,0))*Допущения!$C$24 -> 69 | K15: =E15*Допущения!$C$11 -> 41.4 | L15: =E15-F15-G15-H15-I15-J15-K15 -> 81.758824 | M15: =IFERROR(L15/E15,0) -> 0.11849105 | N15: =IFERROR((E15-F15-G15-H15-I15-K15)/E15,0) -> 0.21849105 | O15: =INDEX(Товары!$G$6:$G$17,MATCH($A15,Товары!$B$6:$B$17,0))*INDEX(Товары!$I$6:$I$17,MATCH($A15,Товары!$B$6:$B$17,0))*(1+Допущения!$C$26) -> 315 | P15: =MAX(0.05,MIN(1,INDEX(Допущения!$F$6:$F$8,MATCH($B15,Допущения!$B$6:$B$8,0))+Допущения!$C$25)) -> 0.85 | Q15: =O15*P15 -> 267.75 | R15: =Q15*E15 -> 184747.5 | S15: =Q15*L15 -> 21890.925 | T15: =INDEX(Товары!$E$6:$E$17,MATCH($A15,Товары!$B$6:$B$17,0)) -> 690 | U15: =INDEX(Допущения!$C$6:$C$8,MATCH($B15,Допущения!$B$6:$B$8,0)) -> 0.21 | V15: =INDEX(Допущения!$D$6:$D$8,MATCH($B15,Допущения!$B$6:$B$8,0)) -> 85 | W15: =INDEX(Допущения!$E$6:$E$8,MATCH($B15,Допущения!$B$6:$B$8,0)) -> 45
A16: DU-0004 | B16: Сайт | C16: =INDEX(Товары!$C$6:$C$17,MATCH($A16,Товары!$B$6:$B$17,0)) -> Кружка керамическая | D16: =INDEX(Товары!$D$6:$D$17,MATCH($A16,Товары!$B$6:$B$17,0)) -> Посуда | E16: =T16*(1+Допущения!$C$23) -> 690 | F16: =INDEX(Товары!$F$6:$F$17,MATCH($A16,Товары!$B$6:$B$17,0)) -> 230 | G16: =E16*U16 -> 24.15 | H16: =(V16+W16*(1-P16))/P16 -> 176.84211 | I16: =INDEX(Допущения!$H$6:$H$8,MATCH($B16,Допущения!$B$6:$B$8,0)) -> 0 | J16: =E16*INDEX(Допущения!$G$6:$G$8,MATCH($B16,Допущения!$B$6:$B$8,0))*Допущения!$C$24 -> 89.7 | K16: =E16*Допущения!$C$11 -> 41.4 | L16: =E16-F16-G16-H16-I16-J16-K16 -> 127.90789 | M16: =IFERROR(L16/E16,0) -> 0.18537376 | N16: =IFERROR((E16-F16-G16-H16-I16-K16)/E16,0) -> 0.31537376 | O16: =INDEX(Товары!$G$6:$G$17,MATCH($A16,Товары!$B$6:$B$17,0))*INDEX(Товары!$J$6:$J$17,MATCH($A16,Товары!$B$6:$B$17,0))*(1+Допущения!$C$26) -> 180 | P16: =MAX(0.05,MIN(1,INDEX(Допущения!$F$6:$F$8,MATCH($B16,Допущения!$B$6:$B$8,0))+Допущения!$C$25)) -> 0.95 | Q16: =O16*P16 -> 171 | R16: =Q16*E16 -> 117990 | S16: =Q16*L16 -> 21872.25 | T16: =INDEX(Товары!$E$6:$E$17,MATCH($A16,Товары!$B$6:$B$17,0)) -> 690 | U16: =INDEX(Допущения!$C$6:$C$8,MATCH($B16,Допущения!$B$6:$B$8,0)) -> 0.035 | V16: =INDEX(Допущения!$D$6:$D$8,MATCH($B16,Допущения!$B$6:$B$8,0)) -> 160 | W16: =INDEX(Допущения!$E$6:$E$8,MATCH($B16,Допущения!$B$6:$B$8,0)) -> 160
A17: DU-0005 | B17: Wildberries | C17: =INDEX(Товары!$C$6:$C$17,MATCH($A17,Товары!$B$6:$B$17,0)) -> Набор тарелок | D17: =INDEX(Товары!$D$6:$D$17,MATCH($A17,Товары!$B$6:$B$17,0)) -> Посуда | E17: =T17*(1+Допущения!$C$23) -> 2890 | F17: =INDEX(Товары!$F$6:$F$17,MATCH($A17,Товары!$B$6:$B$17,0)) -> 1150 | G17: =E17*U17 -> 693.6 | H17: =(V17+W17*(1-P17))/P17 -> 132.05128 | I17: =INDEX(Допущения!$H$6:$H$8,MATCH($B17,Допущения!$B$6:$B$8,0)) -> 18 | J17: =E17*INDEX(Допущения!$G$6:$G$8,MATCH($B17,Допущения!$B$6:$B$8,0))*Допущения!$C$24 -> 346.8 | K17: =E17*Допущения!$C$11 -> 173.4 | L17: =E17-F17-G17-H17-I17-J17-K17 -> 376.14872 | M17: =IFERROR(L17/E17,0) -> 0.13015527 | N17: =IFERROR((E17-F17-G17-H17-I17-K17)/E17,0) -> 0.25015527 | O17: =INDEX(Товары!$G$6:$G$17,MATCH($A17,Товары!$B$6:$B$17,0))*INDEX(Товары!$H$6:$H$17,MATCH($A17,Товары!$B$6:$B$17,0))*(1+Допущения!$C$26) -> 104 | P17: =MAX(0.05,MIN(1,INDEX(Допущения!$F$6:$F$8,MATCH($B17,Допущения!$B$6:$B$8,0))+Допущения!$C$25)) -> 0.78 | Q17: =O17*P17 -> 81.12 | R17: =Q17*E17 -> 234436.8 | S17: =Q17*L17 -> 30513.184 | T17: =INDEX(Товары!$E$6:$E$17,MATCH($A17,Товары!$B$6:$B$17,0)) -> 2890 | U17: =INDEX(Допущения!$C$6:$C$8,MATCH($B17,Допущения!$B$6:$B$8,0)) -> 0.24 | V17: =INDEX(Допущения!$D$6:$D$8,MATCH($B17,Допущения!$B$6:$B$8,0)) -> 92 | W17: =INDEX(Допущения!$E$6:$E$8,MATCH($B17,Допущения!$B$6:$B$8,0)) -> 50
A18: DU-0005 | B18: Ozon | C18: =INDEX(Товары!$C$6:$C$17,MATCH($A18,Товары!$B$6:$B$17,0)) -> Набор тарелок | D18: =INDEX(Товары!$D$6:$D$17,MATCH($A18,Товары!$B$6:$B$17,0)) -> Посуда | E18: =T18*(1+Допущения!$C$23) -> 2890 | F18: =INDEX(Товары!$F$6:$F$17,MATCH($A18,Товары!$B$6:$B$17,0)) -> 1150 | G18: =E18*U18 -> 606.9 | H18: =(V18+W18*(1-P18))/P18 -> 107.94118 | I18: =INDEX(Допущения!$H$6:$H$8,MATCH($B18,Допущения!$B$6:$B$8,0)) -> 15 | J18: =E18*INDEX(Допущения!$G$6:$G$8,MATCH($B18,Допущения!$B$6:$B$8,0))*Допущения!$C$24 -> 289 | K18: =E18*Допущения!$C$11 -> 173.4 | L18: =E18-F18-G18-H18-I18-J18-K18 -> 547.75882 | M18: =IFERROR(L18/E18,0) -> 0.18953593 | N18: =IFERROR((E18-F18-G18-H18-I18-K18)/E18,0) -> 0.28953593 | O18: =INDEX(Товары!$G$6:$G$17,MATCH($A18,Товары!$B$6:$B$17,0))*INDEX(Товары!$I$6:$I$17,MATCH($A18,Товары!$B$6:$B$17,0))*(1+Допущения!$C$26) -> 91 | P18: =MAX(0.05,MIN(1,INDEX(Допущения!$F$6:$F$8,MATCH($B18,Допущения!$B$6:$B$8,0))+Допущения!$C$25)) -> 0.85 | Q18: =O18*P18 -> 77.35 | R18: =Q18*E18 -> 223541.5 | S18: =Q18*L18 -> 42369.145 | T18: =INDEX(Товары!$E$6:$E$17,MATCH($A18,Товары!$B$6:$B$17,0)) -> 2890 | U18: =INDEX(Допущения!$C$6:$C$8,MATCH($B18,Допущения!$B$6:$B$8,0)) -> 0.21 | V18: =INDEX(Допущения!$D$6:$D$8,MATCH($B18,Допущения!$B$6:$B$8,0)) -> 85 | W18: =INDEX(Допущения!$E$6:$E$8,MATCH($B18,Допущения!$B$6:$B$8,0)) -> 45
A19: DU-0005 | B19: Сайт | C19: =INDEX(Товары!$C$6:$C$17,MATCH($A19,Товары!$B$6:$B$17,0)) -> Набор тарелок | D19: =INDEX(Товары!$D$6:$D$17,MATCH($A19,Товары!$B$6:$B$17,0)) -> Посуда | E19: =T19*(1+Допущения!$C$23) -> 2890 | F19: =INDEX(Товары!$F$6:$F$17,MATCH($A19,Товары!$B$6:$B$17,0)) -> 1150 | G19: =E19*U19 -> 101.15 | H19: =(V19+W19*(1-P19))/P19 -> 176.84211 | I19: =INDEX(Допущения!$H$6:$H$8,MATCH($B19,Допущения!$B$6:$B$8,0)) -> 0 | J19: =E19*INDEX(Допущения!$G$6:$G$8,MATCH($B19,Допущения!$B$6:$B$8,0))*Допущения!$C$24 -> 375.7 | K19: =E19*Допущения!$C$11 -> 173.4 | L19: =E19-F19-G19-H19-I19-J19-K19 -> 912.90789 | M19: =IFERROR(L19/E19,0) -> 0.31588508 | N19: =IFERROR((E19-F19-G19-H19-I19-K19)/E19,0) -> 0.44588508 | O19: =INDEX(Товары!$G$6:$G$17,MATCH($A19,Товары!$B$6:$B$17,0))*INDEX(Товары!$J$6:$J$17,MATCH($A19,Товары!$B$6:$B$17,0))*(1+Допущения!$C$26) -> 65 | P19: =MAX(0.05,MIN(1,INDEX(Допущения!$F$6:$F$8,MATCH($B19,Допущения!$B$6:$B$8,0))+Допущения!$C$25)) -> 0.95 | Q19: =O19*P19 -> 61.75 | R19: =Q19*E19 -> 178457.5 | S19: =Q19*L19 -> 56372.062 | T19: =INDEX(Товары!$E$6:$E$17,MATCH($A19,Товары!$B$6:$B$17,0)) -> 2890 | U19: =INDEX(Допущения!$C$6:$C$8,MATCH($B19,Допущения!$B$6:$B$8,0)) -> 0.035 | V19: =INDEX(Допущения!$D$6:$D$8,MATCH($B19,Допущения!$B$6:$B$8,0)) -> 160 | W19: =INDEX(Допущения!$E$6:$E$8,MATCH($B19,Допущения!$B$6:$B$8,0)) -> 160
A20: DU-0006 | B20: Wildberries | C20: =INDEX(Товары!$C$6:$C$17,MATCH($A20,Товары!$B$6:$B$17,0)) -> Френч-пресс | D20: =INDEX(Товары!$D$6:$D$17,MATCH($A20,Товары!$B$6:$B$17,0)) -> Посуда | E20: =T20*(1+Допущения!$C$23) -> 1490 | F20: =INDEX(Товары!$F$6:$F$17,MATCH($A20,Товары!$B$6:$B$17,0)) -> 560 | G20: =E20*U20 -> 357.6 | H20: =(V20+W20*(1-P20))/P20 -> 132.05128 | I20: =INDEX(Допущения!$H$6:$H$8,MATCH($B20,Допущения!$B$6:$B$8,0)) -> 18 | J20: =E20*INDEX(Допущения!$G$6:$G$8,MATCH($B20,Допущения!$B$6:$B$8,0))*Допущения!$C$24 -> 178.8 | K20: =E20*Допущения!$C$11 -> 89.4 | L20: =E20-F20-G20-H20-I20-J20-K20 -> 154.14872 | M20: =IFERROR(L20/E20,0) -> 0.10345552 | N20: =IFERROR((E20-F20-G20-H20-I20-K20)/E20,0) -> 0.22345552 | O20: =INDEX(Товары!$G$6:$G$17,MATCH($A20,Товары!$B$6:$B$17,0))*INDEX(Товары!$H$6:$H$17,MATCH($A20,Товары!$B$6:$B$17,0))*(1+Допущения!$C$26) -> 171 | P20: =MAX(0.05,MIN(1,INDEX(Допущения!$F$6:$F$8,MATCH($B20,Допущения!$B$6:$B$8,0))+Допущения!$C$25)) -> 0.78 | Q20: =O20*P20 -> 133.38 | R20: =Q20*E20 -> 198736.2 | S20: =Q20*L20 -> 20560.356 | T20: =INDEX(Товары!$E$6:$E$17,MATCH($A20,Товары!$B$6:$B$17,0)) -> 1490 | U20: =INDEX(Допущения!$C$6:$C$8,MATCH($B20,Допущения!$B$6:$B$8,0)) -> 0.24 | V20: =INDEX(Допущения!$D$6:$D$8,MATCH($B20,Допущения!$B$6:$B$8,0)) -> 92 | W20: =INDEX(Допущения!$E$6:$E$8,MATCH($B20,Допущения!$B$6:$B$8,0)) -> 50
A21: DU-0006 | B21: Ozon | C21: =INDEX(Товары!$C$6:$C$17,MATCH($A21,Товары!$B$6:$B$17,0)) -> Френч-пресс | D21: =INDEX(Товары!$D$6:$D$17,MATCH($A21,Товары!$B$6:$B$17,0)) -> Посуда | E21: =T21*(1+Допущения!$C$23) -> 1490 | F21: =INDEX(Товары!$F$6:$F$17,MATCH($A21,Товары!$B$6:$B$17,0)) -> 560 | G21: =E21*U21 -> 312.9 | H21: =(V21+W21*(1-P21))/P21 -> 107.94118 | I21: =INDEX(Допущения!$H$6:$H$8,MATCH($B21,Допущения!$B$6:$B$8,0)) -> 15 | J21: =E21*INDEX(Допущения!$G$6:$G$8,MATCH($B21,Допущения!$B$6:$B$8,0))*Допущения!$C$24 -> 149 | K21: =E21*Допущения!$C$11 -> 89.4 | L21: =E21-F21-G21-H21-I21-J21-K21 -> 255.75882 | M21: =IFERROR(L21/E21,0) -> 0.17165022 | N21: =IFERROR((E21-F21-G21-H21-I21-K21)/E21,0) -> 0.27165022 | O21: =INDEX(Товары!$G$6:$G$17,MATCH($A21,Товары!$B$6:$B$17,0))*INDEX(Товары!$I$6:$I$17,MATCH($A21,Товары!$B$6:$B$17,0))*(1+Допущения!$C$26) -> 133 | P21: =MAX(0.05,MIN(1,INDEX(Допущения!$F$6:$F$8,MATCH($B21,Допущения!$B$6:$B$8,0))+Допущения!$C$25)) -> 0.85 | Q21: =O21*P21 -> 113.05 | R21: =Q21*E21 -> 168444.5 | S21: =Q21*L21 -> 28913.535 | T21: =INDEX(Товары!$E$6:$E$17,MATCH($A21,Товары!$B$6:$B$17,0)) -> 1490 | U21: =INDEX(Допущения!$C$6:$C$8,MATCH($B21,Допущения!$B$6:$B$8,0)) -> 0.21 | V21: =INDEX(Допущения!$D$6:$D$8,MATCH($B21,Допущения!$B$6:$B$8,0)) -> 85 | W21: =INDEX(Допущения!$E$6:$E$8,MATCH($B21,Допущения!$B$6:$B$8,0)) -> 45
A22: DU-0006 | B22: Сайт | C22: =INDEX(Товары!$C$6:$C$17,MATCH($A22,Товары!$B$6:$B$17,0)) -> Френч-пресс | D22: =INDEX(Товары!$D$6:$D$17,MATCH($A22,Товары!$B$6:$B$17,0)) -> Посуда | E22: =T22*(1+Допущения!$C$23) -> 1490 | F22: =INDEX(Товары!$F$6:$F$17,MATCH($A22,Товары!$B$6:$B$17,0)) -> 560 | G22: =E22*U22 -> 52.15 | H22: =(V22+W22*(1-P22))/P22 -> 176.84211 | I22: =INDEX(Допущения!$H$6:$H$8,MATCH($B22,Допущения!$B$6:$B$8,0)) -> 0 | J22: =E22*INDEX(Допущения!$G$6:$G$8,MATCH($B22,Допущения!$B$6:$B$8,0))*Допущения!$C$24 -> 193.7 | K22: =E22*Допущения!$C$11 -> 89.4 | L22: =E22-F22-G22-H22-I22-J22-K22 -> 417.90789 | M22: =IFERROR(L22/E22,0) -> 0.2804751 | N22: =IFERROR((E22-F22-G22-H22-I22-K22)/E22,0) -> 0.4104751 | O22: =INDEX(Товары!$G$6:$G$17,MATCH($A22,Товары!$B$6:$B$17,0))*INDEX(Товары!$J$6:$J$17,MATCH($A22,Товары!$B$6:$B$17,0))*(1+Допущения!$C$26) -> 76 | P22: =MAX(0.05,MIN(1,INDEX(Допущения!$F$6:$F$8,MATCH($B22,Допущения!$B$6:$B$8,0))+Допущения!$C$25)) -> 0.95 | Q22: =O22*P22 -> 72.2 | R22: =Q22*E22 -> 107578 | S22: =Q22*L22 -> 30172.95 | T22: =INDEX(Товары!$E$6:$E$17,MATCH($A22,Товары!$B$6:$B$17,0)) -> 1490 | U22: =INDEX(Допущения!$C$6:$C$8,MATCH($B22,Допущения!$B$6:$B$8,0)) -> 0.035 | V22: =INDEX(Допущения!$D$6:$D$8,MATCH($B22,Допущения!$B$6:$B$8,0)) -> 160 | W22: =INDEX(Допущения!$E$6:$E$8,MATCH($B22,Допущения!$B$6:$B$8,0)) -> 160
A23: DU-0007 | B23: Wildberries | C23: =INDEX(Товары!$C$6:$C$17,MATCH($A23,Товары!$B$6:$B$17,0)) -> Органайзер для ящика | D23: =INDEX(Товары!$D$6:$D$17,MATCH($A23,Товары!$B$6:$B$17,0)) -> Хранение | E23: =T23*(1+Допущения!$C$23) -> 590 | F23: =INDEX(Товары!$F$6:$F$17,MATCH($A23,Товары!$B$6:$B$17,0)) -> 260 | G23: =E23*U23 -> 141.6 | H23: =(V23+W23*(1-P23))/P23 -> 132.05128 | I23: =INDEX(Допущения!$H$6:$H$8,MATCH($B23,Допущения!$B$6:$B$8,0)) -> 18 | J23: =E23*INDEX(Допущения!$G$6:$G$8,MATCH($B23,Допущения!$B$6:$B$8,0))*Допущения!$C$24 -> 70.8 | K23: =E23*Допущения!$C$11 -> 35.4 | L23: =E23-F23-G23-H23-I23-J23-K23 -> -67.851282 | M23: =IFERROR(L23/E23,0) -> -0.11500217 | N23: =IFERROR((E23-F23-G23-H23-I23-K23)/E23,0) -> 0.004997827 | O23: =INDEX(Товары!$G$6:$G$17,MATCH($A23,Товары!$B$6:$B$17,0))*INDEX(Товары!$H$6:$H$17,MATCH($A23,Товары!$B$6:$B$17,0))*(1+Допущения!$C$26) -> 286 | P23: =MAX(0.05,MIN(1,INDEX(Допущения!$F$6:$F$8,MATCH($B23,Допущения!$B$6:$B$8,0))+Допущения!$C$25)) -> 0.78 | Q23: =O23*P23 -> 223.08 | R23: =Q23*E23 -> 131617.2 | S23: =Q23*L23 -> -15136.264 | T23: =INDEX(Товары!$E$6:$E$17,MATCH($A23,Товары!$B$6:$B$17,0)) -> 590 | U23: =INDEX(Допущения!$C$6:$C$8,MATCH($B23,Допущения!$B$6:$B$8,0)) -> 0.24 | V23: =INDEX(Допущения!$D$6:$D$8,MATCH($B23,Допущения!$B$6:$B$8,0)) -> 92 | W23: =INDEX(Допущения!$E$6:$E$8,MATCH($B23,Допущения!$B$6:$B$8,0)) -> 50
A24: DU-0007 | B24: Ozon | C24: =INDEX(Товары!$C$6:$C$17,MATCH($A24,Товары!$B$6:$B$17,0)) -> Органайзер для ящика | D24: =INDEX(Товары!$D$6:$D$17,MATCH($A24,Товары!$B$6:$B$17,0)) -> Хранение | E24: =T24*(1+Допущения!$C$23) -> 590 | F24: =INDEX(Товары!$F$6:$F$17,MATCH($A24,Товары!$B$6:$B$17,0)) -> 260 | G24: =E24*U24 -> 123.9 | H24: =(V24+W24*(1-P24))/P24 -> 107.94118 | I24: =INDEX(Допущения!$H$6:$H$8,MATCH($B24,Допущения!$B$6:$B$8,0)) -> 15 | J24: =E24*INDEX(Допущения!$G$6:$G$8,MATCH($B24,Допущения!$B$6:$B$8,0))*Допущения!$C$24 -> 59 | K24: =E24*Допущения!$C$11 -> 35.4 | L24: =E24-F24-G24-H24-I24-J24-K24 -> -11.241176 | M24: =IFERROR(L24/E24,0) -> -0.019052841 | N24: =IFERROR((E24-F24-G24-H24-I24-K24)/E24,0) -> 0.080947159 | O24: =INDEX(Товары!$G$6:$G$17,MATCH($A24,Товары!$B$6:$B$17,0))*INDEX(Товары!$I$6:$I$17,MATCH($A24,Товары!$B$6:$B$17,0))*(1+Допущения!$C$26) -> 156 | P24: =MAX(0.05,MIN(1,INDEX(Допущения!$F$6:$F$8,MATCH($B24,Допущения!$B$6:$B$8,0))+Допущения!$C$25)) -> 0.85 | Q24: =O24*P24 -> 132.6 | R24: =Q24*E24 -> 78234 | S24: =Q24*L24 -> -1490.58 | T24: =INDEX(Товары!$E$6:$E$17,MATCH($A24,Товары!$B$6:$B$17,0)) -> 590 | U24: =INDEX(Допущения!$C$6:$C$8,MATCH($B24,Допущения!$B$6:$B$8,0)) -> 0.21 | V24: =INDEX(Допущения!$D$6:$D$8,MATCH($B24,Допущения!$B$6:$B$8,0)) -> 85 | W24: =INDEX(Допущения!$E$6:$E$8,MATCH($B24,Допущения!$B$6:$B$8,0)) -> 45
A25: DU-0007 | B25: Сайт | C25: =INDEX(Товары!$C$6:$C$17,MATCH($A25,Товары!$B$6:$B$17,0)) -> Органайзер для ящика | D25: =INDEX(Товары!$D$6:$D$17,MATCH($A25,Товары!$B$6:$B$17,0)) -> Хранение | E25: =T25*(1+Допущения!$C$23) -> 590 | F25: =INDEX(Товары!$F$6:$F$17,MATCH($A25,Товары!$B$6:$B$17,0)) -> 260 | G25: =E25*U25 -> 20.65 | H25: =(V25+W25*(1-P25))/P25 -> 176.84211 | I25: =INDEX(Допущения!$H$6:$H$8,MATCH($B25,Допущения!$B$6:$B$8,0)) -> 0 | J25: =E25*INDEX(Допущения!$G$6:$G$8,MATCH($B25,Допущения!$B$6:$B$8,0))*Допущения!$C$24 -> 76.7 | K25: =E25*Допущения!$C$11 -> 35.4 | L25: =E25-F25-G25-H25-I25-J25-K25 -> 20.407895 | M25: =IFERROR(L25/E25,0) -> 0.034589652 | N25: =IFERROR((E25-F25-G25-H25-I25-K25)/E25,0) -> 0.16458965 | O25: =INDEX(Товары!$G$6:$G$17,MATCH($A25,Товары!$B$6:$B$17,0))*INDEX(Товары!$J$6:$J$17,MATCH($A25,Товары!$B$6:$B$17,0))*(1+Допущения!$C$26) -> 78 | P25: =MAX(0.05,MIN(1,INDEX(Допущения!$F$6:$F$8,MATCH($B25,Допущения!$B$6:$B$8,0))+Допущения!$C$25)) -> 0.95 | Q25: =O25*P25 -> 74.1 | R25: =Q25*E25 -> 43719 | S25: =Q25*L25 -> 1512.225 | T25: =INDEX(Товары!$E$6:$E$17,MATCH($A25,Товары!$B$6:$B$17,0)) -> 590 | U25: =INDEX(Допущения!$C$6:$C$8,MATCH($B25,Допущения!$B$6:$B$8,0)) -> 0.035 | V25: =INDEX(Допущения!$D$6:$D$8,MATCH($B25,Допущения!$B$6:$B$8,0)) -> 160 | W25: =INDEX(Допущения!$E$6:$E$8,MATCH($B25,Допущения!$B$6:$B$8,0)) -> 160
A26: DU-0008 | B26: Wildberries | C26: =INDEX(Товары!$C$6:$C$17,MATCH($A26,Товары!$B$6:$B$17,0)) -> Корзина плетёная | D26: =INDEX(Товары!$D$6:$D$17,MATCH($A26,Товары!$B$6:$B$17,0)) -> Хранение | E26: =T26*(1+Допущения!$C$23) -> 690 | F26: =INDEX(Товары!$F$6:$F$17,MATCH($A26,Товары!$B$6:$B$17,0)) -> 380 | G26: =E26*U26 -> 165.6 | H26: =(V26+W26*(1-P26))/P26 -> 132.05128 | I26: =INDEX(Допущения!$H$6:$H$8,MATCH($B26,Допущения!$B$6:$B$8,0)) -> 18 | J26: =E26*INDEX(Допущения!$G$6:$G$8,MATCH($B26,Допущения!$B$6:$B$8,0))*Допущения!$C$24 -> 82.8 | K26: =E26*Допущения!$C$11 -> 41.4 | L26: =E26-F26-G26-H26-I26-J26-K26 -> -129.85128 | M26: =IFERROR(L26/E26,0) -> -0.18819026 | N26: =IFERROR((E26-F26-G26-H26-I26-K26)/E26,0) -> -0.068190264 | O26: =INDEX(Товары!$G$6:$G$17,MATCH($A26,Товары!$B$6:$B$17,0))*INDEX(Товары!$H$6:$H$17,MATCH($A26,Товары!$B$6:$B$17,0))*(1+Допущения!$C$26) -> 264 | P26: =MAX(0.05,MIN(1,INDEX(Допущения!$F$6:$F$8,MATCH($B26,Допущения!$B$6:$B$8,0))+Допущения!$C$25)) -> 0.78 | Q26: =O26*P26 -> 205.92 | R26: =Q26*E26 -> 142084.8 | S26: =Q26*L26 -> -26738.976 | T26: =INDEX(Товары!$E$6:$E$17,MATCH($A26,Товары!$B$6:$B$17,0)) -> 690 | U26: =INDEX(Допущения!$C$6:$C$8,MATCH($B26,Допущения!$B$6:$B$8,0)) -> 0.24 | V26: =INDEX(Допущения!$D$6:$D$8,MATCH($B26,Допущения!$B$6:$B$8,0)) -> 92 | W26: =INDEX(Допущения!$E$6:$E$8,MATCH($B26,Допущения!$B$6:$B$8,0)) -> 50
A27: DU-0008 | B27: Ozon | C27: =INDEX(Товары!$C$6:$C$17,MATCH($A27,Товары!$B$6:$B$17,0)) -> Корзина плетёная | D27: =INDEX(Товары!$D$6:$D$17,MATCH($A27,Товары!$B$6:$B$17,0)) -> Хранение | E27: =T27*(1+Допущения!$C$23) -> 690 | F27: =INDEX(Товары!$F$6:$F$17,MATCH($A27,Товары!$B$6:$B$17,0)) -> 380 | G27: =E27*U27 -> 144.9 | H27: =(V27+W27*(1-P27))/P27 -> 107.94118 | I27: =INDEX(Допущения!$H$6:$H$8,MATCH($B27,Допущения!$B$6:$B$8,0)) -> 15 | J27: =E27*INDEX(Допущения!$G$6:$G$8,MATCH($B27,Допущения!$B$6:$B$8,0))*Допущения!$C$24 -> 69 | K27: =E27*Допущения!$C$11 -> 41.4 | L27: =E27-F27-G27-H27-I27-J27-K27 -> -68.241176 | M27: =IFERROR(L27/E27,0) -> -0.098900256 | N27: =IFERROR((E27-F27-G27-H27-I27-K27)/E27,0) -> 0.0010997442 | O27: =INDEX(Товары!$G$6:$G$17,MATCH($A27,Товары!$B$6:$B$17,0))*INDEX(Товары!$I$6:$I$17,MATCH($A27,Товары!$B$6:$B$17,0))*(1+Допущения!$C$26) -> 168 | P27: =MAX(0.05,MIN(1,INDEX(Допущения!$F$6:$F$8,MATCH($B27,Допущения!$B$6:$B$8,0))+Допущения!$C$25)) -> 0.85 | Q27: =O27*P27 -> 142.8 | R27: =Q27*E27 -> 98532 | S27: =Q27*L27 -> -9744.84 | T27: =INDEX(Товары!$E$6:$E$17,MATCH($A27,Товары!$B$6:$B$17,0)) -> 690 | U27: =INDEX(Допущения!$C$6:$C$8,MATCH($B27,Допущения!$B$6:$B$8,0)) -> 0.21 | V27: =INDEX(Допущения!$D$6:$D$8,MATCH($B27,Допущения!$B$6:$B$8,0)) -> 85 | W27: =INDEX(Допущения!$E$6:$E$8,MATCH($B27,Допущения!$B$6:$B$8,0)) -> 45
A28: DU-0008 | B28: Сайт | C28: =INDEX(Товары!$C$6:$C$17,MATCH($A28,Товары!$B$6:$B$17,0)) -> Корзина плетёная | D28: =INDEX(Товары!$D$6:$D$17,MATCH($A28,Товары!$B$6:$B$17,0)) -> Хранение | E28: =T28*(1+Допущения!$C$23) -> 690 | F28: =INDEX(Товары!$F$6:$F$17,MATCH($A28,Товары!$B$6:$B$17,0)) -> 380 | G28: =E28*U28 -> 24.15 | H28: =(V28+W28*(1-P28))/P28 -> 176.84211 | I28: =INDEX(Допущения!$H$6:$H$8,MATCH($B28,Допущения!$B$6:$B$8,0)) -> 0 | J28: =E28*INDEX(Допущения!$G$6:$G$8,MATCH($B28,Допущения!$B$6:$B$8,0))*Допущения!$C$24 -> 89.7 | K28: =E28*Допущения!$C$11 -> 41.4 | L28: =E28-F28-G28-H28-I28-J28-K28 -> -22.092105 | M28: =IFERROR(L28/E28,0) -> -0.032017544 | N28: =IFERROR((E28-F28-G28-H28-I28-K28)/E28,0) -> 0.097982456 | O28: =INDEX(Товары!$G$6:$G$17,MATCH($A28,Товары!$B$6:$B$17,0))*INDEX(Товары!$J$6:$J$17,MATCH($A28,Товары!$B$6:$B$17,0))*(1+Допущения!$C$26) -> 48 | P28: =MAX(0.05,MIN(1,INDEX(Допущения!$F$6:$F$8,MATCH($B28,Допущения!$B$6:$B$8,0))+Допущения!$C$25)) -> 0.95 | Q28: =O28*P28 -> 45.6 | R28: =Q28*E28 -> 31464 | S28: =Q28*L28 -> -1007.4 | T28: =INDEX(Товары!$E$6:$E$17,MATCH($A28,Товары!$B$6:$B$17,0)) -> 690 | U28: =INDEX(Допущения!$C$6:$C$8,MATCH($B28,Допущения!$B$6:$B$8,0)) -> 0.035 | V28: =INDEX(Допущения!$D$6:$D$8,MATCH($B28,Допущения!$B$6:$B$8,0)) -> 160 | W28: =INDEX(Допущения!$E$6:$E$8,MATCH($B28,Допущения!$B$6:$B$8,0)) -> 160
A29: DU-0009 | B29: Wildberries | C29: =INDEX(Товары!$C$6:$C$17,MATCH($A29,Товары!$B$6:$B$17,0)) -> Свеча ароматическая | D29: =INDEX(Товары!$D$6:$D$17,MATCH($A29,Товары!$B$6:$B$17,0)) -> Декор | E29: =T29*(1+Допущения!$C$23) -> 490 | F29: =INDEX(Товары!$F$6:$F$17,MATCH($A29,Товары!$B$6:$B$17,0)) -> 210 | G29: =E29*U29 -> 117.6 | H29: =(V29+W29*(1-P29))/P29 -> 132.05128 | I29: =INDEX(Допущения!$H$6:$H$8,MATCH($B29,Допущения!$B$6:$B$8,0)) -> 18 | J29: =E29*INDEX(Допущения!$G$6:$G$8,MATCH($B29,Допущения!$B$6:$B$8,0))*Допущения!$C$24 -> 58.8 | K29: =E29*Допущения!$C$11 -> 29.4 | L29: =E29-F29-G29-H29-I29-J29-K29 -> -75.851282 | M29: =IFERROR(L29/E29,0) -> -0.15479853 | N29: =IFERROR((E29-F29-G29-H29-I29-K29)/E29,0) -> -0.034798535 | O29: =INDEX(Товары!$G$6:$G$17,MATCH($A29,Товары!$B$6:$B$17,0))*INDEX(Товары!$H$6:$H$17,MATCH($A29,Товары!$B$6:$B$17,0))*(1+Допущения!$C$26) -> 550 | P29: =MAX(0.05,MIN(1,INDEX(Допущения!$F$6:$F$8,MATCH($B29,Допущения!$B$6:$B$8,0))+Допущения!$C$25)) -> 0.78 | Q29: =O29*P29 -> 429 | R29: =Q29*E29 -> 210210 | S29: =Q29*L29 -> -32540.2 | T29: =INDEX(Товары!$E$6:$E$17,MATCH($A29,Товары!$B$6:$B$17,0)) -> 490 | U29: =INDEX(Допущения!$C$6:$C$8,MATCH($B29,Допущения!$B$6:$B$8,0)) -> 0.24 | V29: =INDEX(Допущения!$D$6:$D$8,MATCH($B29,Допущения!$B$6:$B$8,0)) -> 92 | W29: =INDEX(Допущения!$E$6:$E$8,MATCH($B29,Допущения!$B$6:$B$8,0)) -> 50
A30: DU-0009 | B30: Ozon | C30: =INDEX(Товары!$C$6:$C$17,MATCH($A30,Товары!$B$6:$B$17,0)) -> Свеча ароматическая | D30: =INDEX(Товары!$D$6:$D$17,MATCH($A30,Товары!$B$6:$B$17,0)) -> Декор | E30: =T30*(1+Допущения!$C$23) -> 490 | F30: =INDEX(Товары!$F$6:$F$17,MATCH($A30,Товары!$B$6:$B$17,0)) -> 210 | G30: =E30*U30 -> 102.9 | H30: =(V30+W30*(1-P30))/P30 -> 107.94118 | I30: =INDEX(Допущения!$H$6:$H$8,MATCH($B30,Допущения!$B$6:$B$8,0)) -> 15 | J30: =E30*INDEX(Допущения!$G$6:$G$8,MATCH($B30,Допущения!$B$6:$B$8,0))*Допущения!$C$24 -> 49 | K30: =E30*Допущения!$C$11 -> 29.4 | L30: =E30-F30-G30-H30-I30-J30-K30 -> -24.241176 | M30: =IFERROR(L30/E30,0) -> -0.049471789 | N30: =IFERROR((E30-F30-G30-H30-I30-K30)/E30,0) -> 0.050528211 | O30: =INDEX(Товары!$G$6:$G$17,MATCH($A30,Товары!$B$6:$B$17,0))*INDEX(Товары!$I$6:$I$17,MATCH($A30,Товары!$B$6:$B$17,0))*(1+Допущения!$C$26) -> 385 | P30: =MAX(0.05,MIN(1,INDEX(Допущения!$F$6:$F$8,MATCH($B30,Допущения!$B$6:$B$8,0))+Допущения!$C$25)) -> 0.85 | Q30: =O30*P30 -> 327.25 | R30: =Q30*E30 -> 160352.5 | S30: =Q30*L30 -> -7932.925 | T30: =INDEX(Товары!$E$6:$E$17,MATCH($A30,Товары!$B$6:$B$17,0)) -> 490 | U30: =INDEX(Допущения!$C$6:$C$8,MATCH($B30,Допущения!$B$6:$B$8,0)) -> 0.21 | V30: =INDEX(Допущения!$D$6:$D$8,MATCH($B30,Допущения!$B$6:$B$8,0)) -> 85 | W30: =INDEX(Допущения!$E$6:$E$8,MATCH($B30,Допущения!$B$6:$B$8,0)) -> 45
A31: DU-0009 | B31: Сайт | C31: =INDEX(Товары!$C$6:$C$17,MATCH($A31,Товары!$B$6:$B$17,0)) -> Свеча ароматическая | D31: =INDEX(Товары!$D$6:$D$17,MATCH($A31,Товары!$B$6:$B$17,0)) -> Декор | E31: =T31*(1+Допущения!$C$23) -> 490 | F31: =INDEX(Товары!$F$6:$F$17,MATCH($A31,Товары!$B$6:$B$17,0)) -> 210 | G31: =E31*U31 -> 17.15 | H31: =(V31+W31*(1-P31))/P31 -> 176.84211 | I31: =INDEX(Допущения!$H$6:$H$8,MATCH($B31,Допущения!$B$6:$B$8,0)) -> 0 | J31: =E31*INDEX(Допущения!$G$6:$G$8,MATCH($B31,Допущения!$B$6:$B$8,0))*Допущения!$C$24 -> 63.7 | K31: =E31*Допущения!$C$11 -> 29.4 | L31: =E31-F31-G31-H31-I31-J31-K31 -> -7.0921053 | M31: =IFERROR(L31/E31,0) -> -0.014473684 | N31: =IFERROR((E31-F31-G31-H31-I31-K31)/E31,0) -> 0.11552632 | O31: =INDEX(Товары!$G$6:$G$17,MATCH($A31,Товары!$B$6:$B$17,0))*INDEX(Товары!$J$6:$J$17,MATCH($A31,Товары!$B$6:$B$17,0))*(1+Допущения!$C$26) -> 165 | P31: =MAX(0.05,MIN(1,INDEX(Допущения!$F$6:$F$8,MATCH($B31,Допущения!$B$6:$B$8,0))+Допущения!$C$25)) -> 0.95 | Q31: =O31*P31 -> 156.75 | R31: =Q31*E31 -> 76807.5 | S31: =Q31*L31 -> -1111.6875 | T31: =INDEX(Товары!$E$6:$E$17,MATCH($A31,Товары!$B$6:$B$17,0)) -> 490 | U31: =INDEX(Допущения!$C$6:$C$8,MATCH($B31,Допущения!$B$6:$B$8,0)) -> 0.035 | V31: =INDEX(Допущения!$D$6:$D$8,MATCH($B31,Допущения!$B$6:$B$8,0)) -> 160 | W31: =INDEX(Допущения!$E$6:$E$8,MATCH($B31,Допущения!$B$6:$B$8,0)) -> 160
A32: DU-0010 | B32: Wildberries | C32: =INDEX(Товары!$C$6:$C$17,MATCH($A32,Товары!$B$6:$B$17,0)) -> Ваза стеклянная | D32: =INDEX(Товары!$D$6:$D$17,MATCH($A32,Товары!$B$6:$B$17,0)) -> Декор | E32: =T32*(1+Допущения!$C$23) -> 1890 | F32: =INDEX(Товары!$F$6:$F$17,MATCH($A32,Товары!$B$6:$B$17,0)) -> 720 | G32: =E32*U32 -> 453.6 | H32: =(V32+W32*(1-P32))/P32 -> 132.05128 | I32: =INDEX(Допущения!$H$6:$H$8,MATCH($B32,Допущения!$B$6:$B$8,0)) -> 18 | J32: =E32*INDEX(Допущения!$G$6:$G$8,MATCH($B32,Допущения!$B$6:$B$8,0))*Допущения!$C$24 -> 226.8 | K32: =E32*Допущения!$C$11 -> 113.4 | L32: =E32-F32-G32-H32-I32-J32-K32 -> 226.14872 | M32: =IFERROR(L32/E32,0) -> 0.11965541 | N32: =IFERROR((E32-F32-G32-H32-I32-K32)/E32,0) -> 0.23965541 | O32: =INDEX(Товары!$G$6:$G$17,MATCH($A32,Товары!$B$6:$B$17,0))*INDEX(Товары!$H$6:$H$17,MATCH($A32,Товары!$B$6:$B$17,0))*(1+Допущения!$C$26) -> 96 | P32: =MAX(0.05,MIN(1,INDEX(Допущения!$F$6:$F$8,MATCH($B32,Допущения!$B$6:$B$8,0))+Допущения!$C$25)) -> 0.78 | Q32: =O32*P32 -> 74.88 | R32: =Q32*E32 -> 141523.2 | S32: =Q32*L32 -> 16934.016 | T32: =INDEX(Товары!$E$6:$E$17,MATCH($A32,Товары!$B$6:$B$17,0)) -> 1890 | U32: =INDEX(Допущения!$C$6:$C$8,MATCH($B32,Допущения!$B$6:$B$8,0)) -> 0.24 | V32: =INDEX(Допущения!$D$6:$D$8,MATCH($B32,Допущения!$B$6:$B$8,0)) -> 92 | W32: =INDEX(Допущения!$E$6:$E$8,MATCH($B32,Допущения!$B$6:$B$8,0)) -> 50
A33: DU-0010 | B33: Ozon | C33: =INDEX(Товары!$C$6:$C$17,MATCH($A33,Товары!$B$6:$B$17,0)) -> Ваза стеклянная | D33: =INDEX(Товары!$D$6:$D$17,MATCH($A33,Товары!$B$6:$B$17,0)) -> Декор | E33: =T33*(1+Допущения!$C$23) -> 1890 | F33: =INDEX(Товары!$F$6:$F$17,MATCH($A33,Товары!$B$6:$B$17,0)) -> 720 | G33: =E33*U33 -> 396.9 | H33: =(V33+W33*(1-P33))/P33 -> 107.94118 | I33: =INDEX(Допущения!$H$6:$H$8,MATCH($B33,Допущения!$B$6:$B$8,0)) -> 15 | J33: =E33*INDEX(Допущения!$G$6:$G$8,MATCH($B33,Допущения!$B$6:$B$8,0))*Допущения!$C$24 -> 189 | K33: =E33*Допущения!$C$11 -> 113.4 | L33: =E33-F33-G33-H33-I33-J33-K33 -> 347.75882 | M33: =IFERROR(L33/E33,0) -> 0.18399938 | N33: =IFERROR((E33-F33-G33-H33-I33-K33)/E33,0) -> 0.28399938 | O33: =INDEX(Товары!$G$6:$G$17,MATCH($A33,Товары!$B$6:$B$17,0))*INDEX(Товары!$I$6:$I$17,MATCH($A33,Товары!$B$6:$B$17,0))*(1+Допущения!$C$26) -> 84 | P33: =MAX(0.05,MIN(1,INDEX(Допущения!$F$6:$F$8,MATCH($B33,Допущения!$B$6:$B$8,0))+Допущения!$C$25)) -> 0.85 | Q33: =O33*P33 -> 71.4 | R33: =Q33*E33 -> 134946 | S33: =Q33*L33 -> 24829.98 | T33: =INDEX(Товары!$E$6:$E$17,MATCH($A33,Товары!$B$6:$B$17,0)) -> 1890 | U33: =INDEX(Допущения!$C$6:$C$8,MATCH($B33,Допущения!$B$6:$B$8,0)) -> 0.21 | V33: =INDEX(Допущения!$D$6:$D$8,MATCH($B33,Допущения!$B$6:$B$8,0)) -> 85 | W33: =INDEX(Допущения!$E$6:$E$8,MATCH($B33,Допущения!$B$6:$B$8,0)) -> 45
A34: DU-0010 | B34: Сайт | C34: =INDEX(Товары!$C$6:$C$17,MATCH($A34,Товары!$B$6:$B$17,0)) -> Ваза стеклянная | D34: =INDEX(Товары!$D$6:$D$17,MATCH($A34,Товары!$B$6:$B$17,0)) -> Декор | E34: =T34*(1+Допущения!$C$23) -> 1890 | F34: =INDEX(Товары!$F$6:$F$17,MATCH($A34,Товары!$B$6:$B$17,0)) -> 720 | G34: =E34*U34 -> 66.15 | H34: =(V34+W34*(1-P34))/P34 -> 176.84211 | I34: =INDEX(Допущения!$H$6:$H$8,MATCH($B34,Допущения!$B$6:$B$8,0)) -> 0 | J34: =E34*INDEX(Допущения!$G$6:$G$8,MATCH($B34,Допущения!$B$6:$B$8,0))*Допущения!$C$24 -> 245.7 | K34: =E34*Допущения!$C$11 -> 113.4 | L34: =E34-F34-G34-H34-I34-J34-K34 -> 567.90789 | M34: =IFERROR(L34/E34,0) -> 0.30048037 | N34: =IFERROR((E34-F34-G34-H34-I34-K34)/E34,0) -> 0.43048037 | O34: =INDEX(Товары!$G$6:$G$17,MATCH($A34,Товары!$B$6:$B$17,0))*INDEX(Товары!$J$6:$J$17,MATCH($A34,Товары!$B$6:$B$17,0))*(1+Допущения!$C$26) -> 60 | P34: =MAX(0.05,MIN(1,INDEX(Допущения!$F$6:$F$8,MATCH($B34,Допущения!$B$6:$B$8,0))+Допущения!$C$25)) -> 0.95 | Q34: =O34*P34 -> 57 | R34: =Q34*E34 -> 107730 | S34: =Q34*L34 -> 32370.75 | T34: =INDEX(Товары!$E$6:$E$17,MATCH($A34,Товары!$B$6:$B$17,0)) -> 1890 | U34: =INDEX(Допущения!$C$6:$C$8,MATCH($B34,Допущения!$B$6:$B$8,0)) -> 0.035 | V34: =INDEX(Допущения!$D$6:$D$8,MATCH($B34,Допущения!$B$6:$B$8,0)) -> 160 | W34: =INDEX(Допущения!$E$6:$E$8,MATCH($B34,Допущения!$B$6:$B$8,0)) -> 160
A35: DU-0011 | B35: Wildberries | C35: =INDEX(Товары!$C$6:$C$17,MATCH($A35,Товары!$B$6:$B$17,0)) -> Коврик для ванной | D35: =INDEX(Товары!$D$6:$D$17,MATCH($A35,Товары!$B$6:$B$17,0)) -> Ванная | E35: =T35*(1+Допущения!$C$23) -> 1290 | F35: =INDEX(Товары!$F$6:$F$17,MATCH($A35,Товары!$B$6:$B$17,0)) -> 520 | G35: =E35*U35 -> 309.6 | H35: =(V35+W35*(1-P35))/P35 -> 132.05128 | I35: =INDEX(Допущения!$H$6:$H$8,MATCH($B35,Допущения!$B$6:$B$8,0)) -> 18 | J35: =E35*INDEX(Допущения!$G$6:$G$8,MATCH($B35,Допущения!$B$6:$B$8,0))*Допущения!$C$24 -> 154.8 | K35: =E35*Допущения!$C$11 -> 77.4 | L35: =E35-F35-G35-H35-I35-J35-K35 -> 78.148718 | M35: =IFERROR(L35/E35,0) -> 0.060580402 | N35: =IFERROR((E35-F35-G35-H35-I35-K35)/E35,0) -> 0.1805804 | O35: =INDEX(Товары!$G$6:$G$17,MATCH($A35,Товары!$B$6:$B$17,0))*INDEX(Товары!$H$6:$H$17,MATCH($A35,Товары!$B$6:$B$17,0))*(1+Допущения!$C$26) -> 180 | P35: =MAX(0.05,MIN(1,INDEX(Допущения!$F$6:$F$8,MATCH($B35,Допущения!$B$6:$B$8,0))+Допущения!$C$25)) -> 0.78 | Q35: =O35*P35 -> 140.4 | R35: =Q35*E35 -> 181116 | S35: =Q35*L35 -> 10972.08 | T35: =INDEX(Товары!$E$6:$E$17,MATCH($A35,Товары!$B$6:$B$17,0)) -> 1290 | U35: =INDEX(Допущения!$C$6:$C$8,MATCH($B35,Допущения!$B$6:$B$8,0)) -> 0.24 | V35: =INDEX(Допущения!$D$6:$D$8,MATCH($B35,Допущения!$B$6:$B$8,0)) -> 92 | W35: =INDEX(Допущения!$E$6:$E$8,MATCH($B35,Допущения!$B$6:$B$8,0)) -> 50
A36: DU-0011 | B36: Ozon | C36: =INDEX(Товары!$C$6:$C$17,MATCH($A36,Товары!$B$6:$B$17,0)) -> Коврик для ванной | D36: =INDEX(Товары!$D$6:$D$17,MATCH($A36,Товары!$B$6:$B$17,0)) -> Ванная | E36: =T36*(1+Допущения!$C$23) -> 1290 | F36: =INDEX(Товары!$F$6:$F$17,MATCH($A36,Товары!$B$6:$B$17,0)) -> 520 | G36: =E36*U36 -> 270.9 | H36: =(V36+W36*(1-P36))/P36 -> 107.94118 | I36: =INDEX(Допущения!$H$6:$H$8,MATCH($B36,Допущения!$B$6:$B$8,0)) -> 15 | J36: =E36*INDEX(Допущения!$G$6:$G$8,MATCH($B36,Допущения!$B$6:$B$8,0))*Допущения!$C$24 -> 129 | K36: =E36*Допущения!$C$11 -> 77.4 | L36: =E36-F36-G36-H36-I36-J36-K36 -> 169.75882 | M36: =IFERROR(L36/E36,0) -> 0.13159599 | N36: =IFERROR((E36-F36-G36-H36-I36-K36)/E36,0) -> 0.23159599 | O36: =INDEX(Товары!$G$6:$G$17,MATCH($A36,Товары!$B$6:$B$17,0))*INDEX(Товары!$I$6:$I$17,MATCH($A36,Товары!$B$6:$B$17,0))*(1+Допущения!$C$26) -> 126 | P36: =MAX(0.05,MIN(1,INDEX(Допущения!$F$6:$F$8,MATCH($B36,Допущения!$B$6:$B$8,0))+Допущения!$C$25)) -> 0.85 | Q36: =O36*P36 -> 107.1 | R36: =Q36*E36 -> 138159 | S36: =Q36*L36 -> 18181.17 | T36: =INDEX(Товары!$E$6:$E$17,MATCH($A36,Товары!$B$6:$B$17,0)) -> 1290 | U36: =INDEX(Допущения!$C$6:$C$8,MATCH($B36,Допущения!$B$6:$B$8,0)) -> 0.21 | V36: =INDEX(Допущения!$D$6:$D$8,MATCH($B36,Допущения!$B$6:$B$8,0)) -> 85 | W36: =INDEX(Допущения!$E$6:$E$8,MATCH($B36,Допущения!$B$6:$B$8,0)) -> 45
A37: DU-0011 | B37: Сайт | C37: =INDEX(Товары!$C$6:$C$17,MATCH($A37,Товары!$B$6:$B$17,0)) -> Коврик для ванной | D37: =INDEX(Товары!$D$6:$D$17,MATCH($A37,Товары!$B$6:$B$17,0)) -> Ванная | E37: =T37*(1+Допущения!$C$23) -> 1290 | F37: =INDEX(Товары!$F$6:$F$17,MATCH($A37,Товары!$B$6:$B$17,0)) -> 520 | G37: =E37*U37 -> 45.15 | H37: =(V37+W37*(1-P37))/P37 -> 176.84211 | I37: =INDEX(Допущения!$H$6:$H$8,MATCH($B37,Допущения!$B$6:$B$8,0)) -> 0 | J37: =E37*INDEX(Допущения!$G$6:$G$8,MATCH($B37,Допущения!$B$6:$B$8,0))*Допущения!$C$24 -> 167.7 | K37: =E37*Допущения!$C$11 -> 77.4 | L37: =E37-F37-G37-H37-I37-J37-K37 -> 302.90789 | M37: =IFERROR(L37/E37,0) -> 0.23481232 | N37: =IFERROR((E37-F37-G37-H37-I37-K37)/E37,0) -> 0.36481232 | O37: =INDEX(Товары!$G$6:$G$17,MATCH($A37,Товары!$B$6:$B$17,0))*INDEX(Товары!$J$6:$J$17,MATCH($A37,Товары!$B$6:$B$17,0))*(1+Допущения!$C$26) -> 54 | P37: =MAX(0.05,MIN(1,INDEX(Допущения!$F$6:$F$8,MATCH($B37,Допущения!$B$6:$B$8,0))+Допущения!$C$25)) -> 0.95 | Q37: =O37*P37 -> 51.3 | R37: =Q37*E37 -> 66177 | S37: =Q37*L37 -> 15539.175 | T37: =INDEX(Товары!$E$6:$E$17,MATCH($A37,Товары!$B$6:$B$17,0)) -> 1290 | U37: =INDEX(Допущения!$C$6:$C$8,MATCH($B37,Допущения!$B$6:$B$8,0)) -> 0.035 | V37: =INDEX(Допущения!$D$6:$D$8,MATCH($B37,Допущения!$B$6:$B$8,0)) -> 160 | W37: =INDEX(Допущения!$E$6:$E$8,MATCH($B37,Допущения!$B$6:$B$8,0)) -> 160
A38: DU-0012 | B38: Wildberries | C38: =INDEX(Товары!$C$6:$C$17,MATCH($A38,Товары!$B$6:$B$17,0)) -> Держатель для щёток | D38: =INDEX(Товары!$D$6:$D$17,MATCH($A38,Товары!$B$6:$B$17,0)) -> Ванная | E38: =T38*(1+Допущения!$C$23) -> 390 | F38: =INDEX(Товары!$F$6:$F$17,MATCH($A38,Товары!$B$6:$B$17,0)) -> 190 | G38: =E38*U38 -> 93.6 | H38: =(V38+W38*(1-P38))/P38 -> 132.05128 | I38: =INDEX(Допущения!$H$6:$H$8,MATCH($B38,Допущения!$B$6:$B$8,0)) -> 18 | J38: =E38*INDEX(Допущения!$G$6:$G$8,MATCH($B38,Допущения!$B$6:$B$8,0))*Допущения!$C$24 -> 46.8 | K38: =E38*Допущения!$C$11 -> 23.4 | L38: =E38-F38-G38-H38-I38-J38-K38 -> -113.85128 | M38: =IFERROR(L38/E38,0) -> -0.29192636 | N38: =IFERROR((E38-F38-G38-H38-I38-K38)/E38,0) -> -0.17192636 | O38: =INDEX(Товары!$G$6:$G$17,MATCH($A38,Товары!$B$6:$B$17,0))*INDEX(Товары!$H$6:$H$17,MATCH($A38,Товары!$B$6:$B$17,0))*(1+Допущения!$C$26) -> 385 | P38: =MAX(0.05,MIN(1,INDEX(Допущения!$F$6:$F$8,MATCH($B38,Допущения!$B$6:$B$8,0))+Допущения!$C$25)) -> 0.78 | Q38: =O38*P38 -> 300.3 | R38: =Q38*E38 -> 117117 | S38: =Q38*L38 -> -34189.54 | T38: =INDEX(Товары!$E$6:$E$17,MATCH($A38,Товары!$B$6:$B$17,0)) -> 390 | U38: =INDEX(Допущения!$C$6:$C$8,MATCH($B38,Допущения!$B$6:$B$8,0)) -> 0.24 | V38: =INDEX(Допущения!$D$6:$D$8,MATCH($B38,Допущения!$B$6:$B$8,0)) -> 92 | W38: =INDEX(Допущения!$E$6:$E$8,MATCH($B38,Допущения!$B$6:$B$8,0)) -> 50
A39: DU-0012 | B39: Ozon | C39: =INDEX(Товары!$C$6:$C$17,MATCH($A39,Товары!$B$6:$B$17,0)) -> Держатель для щёток | D39: =INDEX(Товары!$D$6:$D$17,MATCH($A39,Товары!$B$6:$B$17,0)) -> Ванная | E39: =T39*(1+Допущения!$C$23) -> 390 | F39: =INDEX(Товары!$F$6:$F$17,MATCH($A39,Товары!$B$6:$B$17,0)) -> 190 | G39: =E39*U39 -> 81.9 | H39: =(V39+W39*(1-P39))/P39 -> 107.94118 | I39: =INDEX(Допущения!$H$6:$H$8,MATCH($B39,Допущения!$B$6:$B$8,0)) -> 15 | J39: =E39*INDEX(Допущения!$G$6:$G$8,MATCH($B39,Допущения!$B$6:$B$8,0))*Допущения!$C$24 -> 39 | K39: =E39*Допущения!$C$11 -> 23.4 | L39: =E39-F39-G39-H39-I39-J39-K39 -> -67.241176 | M39: =IFERROR(L39/E39,0) -> -0.17241327 | N39: =IFERROR((E39-F39-G39-H39-I39-K39)/E39,0) -> -0.072413273 | O39: =INDEX(Товары!$G$6:$G$17,MATCH($A39,Товары!$B$6:$B$17,0))*INDEX(Товары!$I$6:$I$17,MATCH($A39,Товары!$B$6:$B$17,0))*(1+Допущения!$C$26) -> 245 | P39: =MAX(0.05,MIN(1,INDEX(Допущения!$F$6:$F$8,MATCH($B39,Допущения!$B$6:$B$8,0))+Допущения!$C$25)) -> 0.85 | Q39: =O39*P39 -> 208.25 | R39: =Q39*E39 -> 81217.5 | S39: =Q39*L39 -> -14002.975 | T39: =INDEX(Товары!$E$6:$E$17,MATCH($A39,Товары!$B$6:$B$17,0)) -> 390 | U39: =INDEX(Допущения!$C$6:$C$8,MATCH($B39,Допущения!$B$6:$B$8,0)) -> 0.21 | V39: =INDEX(Допущения!$D$6:$D$8,MATCH($B39,Допущения!$B$6:$B$8,0)) -> 85 | W39: =INDEX(Допущения!$E$6:$E$8,MATCH($B39,Допущения!$B$6:$B$8,0)) -> 45
A40: DU-0012 | B40: Сайт | C40: =INDEX(Товары!$C$6:$C$17,MATCH($A40,Товары!$B$6:$B$17,0)) -> Держатель для щёток | D40: =INDEX(Товары!$D$6:$D$17,MATCH($A40,Товары!$B$6:$B$17,0)) -> Ванная | E40: =T40*(1+Допущения!$C$23) -> 390 | F40: =INDEX(Товары!$F$6:$F$17,MATCH($A40,Товары!$B$6:$B$17,0)) -> 190 | G40: =E40*U40 -> 13.65 | H40: =(V40+W40*(1-P40))/P40 -> 176.84211 | I40: =INDEX(Допущения!$H$6:$H$8,MATCH($B40,Допущения!$B$6:$B$8,0)) -> 0 | J40: =E40*INDEX(Допущения!$G$6:$G$8,MATCH($B40,Допущения!$B$6:$B$8,0))*Допущения!$C$24 -> 50.7 | K40: =E40*Допущения!$C$11 -> 23.4 | L40: =E40-F40-G40-H40-I40-J40-K40 -> -64.592105 | M40: =IFERROR(L40/E40,0) -> -0.16562078 | N40: =IFERROR((E40-F40-G40-H40-I40-K40)/E40,0) -> -0.035620783 | O40: =INDEX(Товары!$G$6:$G$17,MATCH($A40,Товары!$B$6:$B$17,0))*INDEX(Товары!$J$6:$J$17,MATCH($A40,Товары!$B$6:$B$17,0))*(1+Допущения!$C$26) -> 70 | P40: =MAX(0.05,MIN(1,INDEX(Допущения!$F$6:$F$8,MATCH($B40,Допущения!$B$6:$B$8,0))+Допущения!$C$25)) -> 0.95 | Q40: =O40*P40 -> 66.5 | R40: =Q40*E40 -> 25935 | S40: =Q40*L40 -> -4295.375 | T40: =INDEX(Товары!$E$6:$E$17,MATCH($A40,Товары!$B$6:$B$17,0)) -> 390 | U40: =INDEX(Допущения!$C$6:$C$8,MATCH($B40,Допущения!$B$6:$B$8,0)) -> 0.035 | V40: =INDEX(Допущения!$D$6:$D$8,MATCH($B40,Допущения!$B$6:$B$8,0)) -> 160 | W40: =INDEX(Допущения!$E$6:$E$8,MATCH($B40,Допущения!$B$6:$B$8,0)) -> 160
C41: Итого в месяц | M41: =IFERROR(S41/R41,0) -> 0.1033886 | O41: =SUM(O5:O40) -> 6310 | Q41: =SUM(Q5:Q40) -> 5244.86 | R41: =SUM(R5:R40) -> 5942848.4 | S41: =SUM(S5:S40) -> 614422.75

Sheet P&L
B2: Отчёт о прибылях и убытках на 2027 год, ₽
B3: ="Сценарий: "&Допущения!C22 -> Сценарий: Базовый
B5: Статья | C5: янв | D5: фев | E5: мар | F5: апр | G5: май | H5: июн | I5: июл | J5: авг | K5: сен | L5: окт | M5: ноя | N5: дек | O5: Итого за год | P5: % выручки
B6: Индекс сезонности | C6: =Допущения!C31 -> 0.92 | D6: =Допущения!D31 -> 0.88 | E6: =Допущения!E31 -> 1.08 | F6: =Допущения!F31 -> 0.93 | G6: =Допущения!G31 -> 0.94 | H6: =Допущения!H31 -> 0.86 | I6: =Допущения!I31 -> 0.87 | J6: =Допущения!J31 -> 0.97 | ... N6: =Допущения!N31 -> 1.4
B7: Фактор роста | C7: =(1+Допущения!$C$13)^0 -> 1 | D7: =(1+Допущения!$C$13)^1 -> 1.02 | E7: =(1+Допущения!$C$13)^2 -> 1.0404 | F7: =(1+Допущения!$C$13)^3 -> 1.061208 | G7: =(1+Допущения!$C$13)^4 -> 1.0824322 | H7: =(1+Допущения!$C$13)^5 -> 1.1040808 | I7: =(1+Допущения!$C$13)^6 -> 1.1261624 | J7: =(1+Допущения!$C$13)^7 -> 1.1486857 | K7: =(1+Допущения!$C$13)^8 -> 1.1716594 | L7: =(1+Допущения!$C$13)^9 -> 1.1950926 | M7: =(1+Допущения!$C$13)^10 -> 1.2189944 | N7: =(1+Допущения!$C$13)^11 -> 1.2433743
B8: Выручка | C8: =SUMPRODUCT('Юнит-экономика'!$Q$5:$Q$40,'Юнит-экономика'!$E$5:$E$40)*C$6*C$7 -> 5467420.5 | D8: =SUMPRODUCT('Юнит-экономика'!$Q$5:$Q$40,'Юнит-экономика'!$E$5:$E$40)*D$6*D$7 -> 5334300.7 | E8: =SUMPRODUCT('Юнит-экономика'!$Q$5:$Q$40,'Юнит-экономика'!$E$5:$E$40)*E$6*E$7 -> 6677574.6 | F8: =SUMPRODUCT('Юнит-экономика'!$Q$5:$Q$40,'Юнит-экономика'!$E$5:$E$40)*F$6*F$7 -> 5865136.4 | G8: =SUMPRODUCT('Юнит-экономика'!$Q$5:$Q$40,'Юнит-экономика'!$E$5:$E$40)*G$6*G$7 -> 6046766.4 | H8: =SUMPRODUCT('Юнит-экономика'!$Q$5:$Q$40,'Юнит-экономика'!$E$5:$E$40)*H$6*H$7 -> 5642791 | I8: =SUMPRODUCT('Юнит-экономика'!$Q$5:$Q$40,'Юнит-экономика'!$E$5:$E$40)*I$6*I$7 -> 5822572.9 | J8: =SUMPRODUCT('Юнит-экономика'!$Q$5:$Q$40,'Юнит-экономика'!$E$5:$E$40)*J$6*J$7 -> 6621670.8 | ... N8: =SUMPRODUCT('Юнит-экономика'!$Q$5:$Q$40,'Юнит-экономика'!$E$5:$E$40)*N$6*N$7 -> 10344859 | O8: =SUM(C8:N8) -> 80213658 | P8: =IFERROR(O8/$O$8,0) -> 1
B9: Себестоимость | C9: =SUMPRODUCT('Юнит-экономика'!$Q$5:$Q$40,'Юнит-экономика'!$F$5:$F$40)*C$6*C$7 -> 2213988.5 | D9: =SUMPRODUCT('Юнит-экономика'!$Q$5:$Q$40,'Юнит-экономика'!$F$5:$F$40)*D$6*D$7 -> 2160082.7 | E9: =SUMPRODUCT('Юнит-экономика'!$Q$5:$Q$40,'Юнит-экономика'!$F$5:$F$40)*E$6*E$7 -> 2704030.7 | F9: =SUMPRODUCT('Юнит-экономика'!$Q$5:$Q$40,'Юнит-экономика'!$F$5:$F$40)*F$6*F$7 -> 2375040.3 | G9: =SUMPRODUCT('Юнит-экономика'!$Q$5:$Q$40,'Юнит-экономика'!$F$5:$F$40)*G$6*G$7 -> 2448590 | H9: =SUMPRODUCT('Юнит-экономика'!$Q$5:$Q$40,'Юнит-экономика'!$F$5:$F$40)*H$6*H$7 -> 2285003.3 | I9: =SUMPRODUCT('Юнит-экономика'!$Q$5:$Q$40,'Юнит-экономика'!$F$5:$F$40)*I$6*I$7 -> 2357804.6 | J9: =SUMPRODUCT('Юнит-экономика'!$Q$5:$Q$40,'Юнит-экономика'!$F$5:$F$40)*J$6*J$7 -> 2681392.9 | ... N9: =SUMPRODUCT('Юнит-экономика'!$Q$5:$Q$40,'Юнит-экономика'!$F$5:$F$40)*N$6*N$7 -> 4189068.4 | O9: =SUM(C9:N9) -> 32481883 | P9: =IFERROR(O9/$O$8,0) -> 0.40494205
B10: Комиссия площадок | C10: =SUMPRODUCT('Юнит-экономика'!$Q$5:$Q$40,'Юнит-экономика'!$G$5:$G$40)*C$6*C$7 -> 1027542.4 | D10: =SUMPRODUCT('Юнит-экономика'!$Q$5:$Q$40,'Юнит-экономика'!$G$5:$G$40)*D$6*D$7 -> 1002524 | E10: =SUMPRODUCT('Юнит-экономика'!$Q$5:$Q$40,'Юнит-экономика'!$G$5:$G$40)*E$6*E$7 -> 1254977.8 | F10: =SUMPRODUCT('Юнит-экономика'!$Q$5:$Q$40,'Юнит-экономика'!$G$5:$G$40)*F$6*F$7 -> 1102288.8 | G10: =SUMPRODUCT('Юнит-экономика'!$Q$5:$Q$40,'Юнит-экономика'!$G$5:$G$40)*G$6*G$7 -> 1136424.2 | H10: =SUMPRODUCT('Юнит-экономика'!$Q$5:$Q$40,'Юнит-экономика'!$G$5:$G$40)*H$6*H$7 -> 1060501.4 | I10: =SUMPRODUCT('Юнит-экономика'!$Q$5:$Q$40,'Юнит-экономика'!$G$5:$G$40)*I$6*I$7 -> 1094289.5 | J10: =SUMPRODUCT('Юнит-экономика'!$Q$5:$Q$40,'Юнит-экономика'!$G$5:$G$40)*J$6*J$7 -> 1244471.3 | ... N10: =SUMPRODUCT('Юнит-экономика'!$Q$5:$Q$40,'Юнит-экономика'!$G$5:$G$40)*N$6*N$7 -> 1944204.1 | O10: =SUM(C10:N10) -> 15075288 | P10: =IFERROR(O10/$O$8,0) -> 0.18793916
